Workbook

Sheet README
A1: Workbook Cleanup Summary | B1: This workbook was cleaned and structured for migration planning and polished demo use.
A2: Second pass completed for MVP use. | B2: Documents was converted from one CSV-packed column into proper fields. Normalized clean tabs were added for Drivers, Documents, Assets, Dispatch, and Payroll. Structured Safety_Events and Compliance_Events tabs were added for app planning.
A3: - Statuses standardized across clean tabs (PAID/PENDING/ON_HOLD, DELIVERED/IN_TRANSIT/PENDING, VALID/EXPIRING_SOON/EXPIRED, OPEN/REVIEWED/CLOSED). | B3: Keep the original tabs for current formulas and dashboards. Use the *_Clean tabs when mapping data into Vercel or a future database.
A4: Latest upgrade | B4: Link wiring added for photos and documents; Vercel export tabs now include direct URLs and a Vercel_Documents export was added.
A5: JSON seed file | B5: See backofficefleet_vercel_seed.json generated alongside this workbook.
A7: Photo Layer Added
A8: Dispatch, document preview, safety, compliance, POD, pickup, delivery, lumper, and seal-related image URLs are now wired for Vercel.
A10: Photo Layer Exports
A11: Use Vercel_Loads, Vercel_Documents, Vercel_Safety, and Vercel_Compliance for image URLs including POD, pickup, delivery, lumper, document previews, safety event images, and compliance evidence.

Sheet Drivers
A1: Total Drivers: | B1: =COUNTA(B6:B16)
A2: Compliant Drivers: | B2: =COUNTIF(E6:E17, "✅ COMPLIANT")
A3: Fleet Health %: | B3: =B2/B1
A5: Driver ID | B5: Full Name | C5: Phone Number | D5: Address | E5: Compliance Status | F5: CDL Expiration Date | G5: Medical Card Expiration | H5: MVR Expiration | I5: Assigned Truck
A6: Driver 1 | B6: John Carter | C6: 206-667-3424 | D6: 1240 W 6th St, Cleveland, OH 44113 | E6: =_xlfn.TEXTJOIN(" | ",TRUE, IF(F6<TODAY(),"❌ CDL EXPIRED",""), IF(G6<TODAY(),"❌ MED CARD EXPIRED",""), IF(H6<TODAY(),"❌ MVR EXPIRED",""), IF(COUNTIFS(Assets!$B$2:$B$26,B6,Assets!$E$2:$E$26,"🔴 EXPIRED")>0,"❌ TRUCK NEEDS SERVICE",""), IF(AND(F6>=TODAY(),G6>=TODAY(),H6>=TODAY(), COUNTIFS(Assets!$B$2:$B$26,B6,Assets!$E$2:$E$26,"🔴 EXPIRED")=0), "✅ COMPLIANT","")) | F6: 46621 | G6: 46094 | H6: 46080 | I6: {=_xlfn.TEXTJOIN(", ", TRUE, _xlfn._xlws.FILTER(Assets!$A$2:$A$26, Assets!$B$2:$B$26 = A6, "No Truck Assigned"))}
A7: Driver 2 | B7: Maria Lopez | C7: 707-773-6386 | D7: 450 N Michigan Ave, Chicago, IL 60611 | E7: =IF(F7 < TODAY(), "❌ CDL EXPIRED", IF(G7 < TODAY(), "❌ MED CARD EXPIRED", IF(COUNTIFS(Assets!$B$2:$B$26, B7, Assets!$E$2:$E$26, "🔴 EXPIRED")>0, "❌ TRUCK NEEDS SERVICE", "✅ COMPLIANT"))) | F7: 46518 | G7: 46596 | H7: =RANDBETWEEN(DATE(2027,3,1),DATE(2027,4,7)) | I7: {=_xlfn.TEXTJOIN(", ", TRUE, _xlfn._xlws.FILTER(Assets!$A$2:$A$26, Assets!$B$2:$B$26 = A7, "No Truck Assigned"))}
A8: Driver 3 | B8: Alex Kim | C8: 675-486-1335 | D8: 780 Peachtree St, Atlanta, GA 30308 | E8: =IF(F8 < TODAY(), "❌ CDL EXPIRED", IF(G8 < TODAY(), "❌ MED CARD EXPIRED", IF(COUNTIFS(Assets!$B$2:$B$26, B8, Assets!$E$2:$E$26, "🔴 EXPIRED")>0, "❌ TRUCK NEEDS SERVICE", "✅ COMPLIANT"))) | F8: 46420 | G8: 46659 | H8: =RANDBETWEEN(DATE(2027,3,1),DATE(2027,4,7)) | I8: {=_xlfn.TEXTJOIN(", ", TRUE, _xlfn._xlws.FILTER(Assets!$A$2:$A$26, Assets!$B$2:$B$26 = A8, "No Truck Assigned"))}
A9: Driver 4 | B9: Priya Patel | C9: 359-469-5960 | D9: 2200 Superior Ave, Cleveland, OH 44114 | E9: =IF(F9 < TODAY(), "❌ CDL EXPIRED", IF(G9 < TODAY(), "❌ MED CARD EXPIRED", IF(COUNTIFS(Assets!$B$2:$B$26, B9, Assets!$E$2:$E$26, "🔴 EXPIRED")>0, "❌ TRUCK NEEDS SERVICE", "✅ COMPLIANT"))) | F9: 46739 | G9: 46486 | H9: =RANDBETWEEN(DATE(2027,3,1),DATE(2027,4,7)) | I9: {=_xlfn.TEXTJOIN(", ", TRUE, _xlfn._xlws.FILTER(Assets!$A$2:$A$26, Assets!$B$2:$B$26 = A9, "No Truck Assigned"))}
A10: Driver 5 | B10: Kenji Tanaka | C10: 871-429-6220 | D10: 115 E Broad St, Columbus, OH 43215 | E10: =IF(F10 < TODAY(), "❌ CDL EXPIRED", IF(G10 < TODAY(), "❌ MED CARD EXPIRED", IF(COUNTIFS(Assets!$B$2:$B$26, B10, Assets!$E$2:$E$26, "🔴 EXPIRED")>0, "❌ TRUCK NEEDS SERVICE", "✅ COMPLIANT"))) | F10: 46577 | G10: 46496 | H10: =RANDBETWEEN(DATE(2027,3,1),DATE(2027,4,7)) | I10: {=_xlfn.TEXTJOIN(", ", TRUE, _xlfn._xlws.FILTER(Assets!$A$2:$A$26, Assets!$B$2:$B$26 = A10, "No Truck Assigned"))}
A11: Driver 6 | B11: Marcus Chen | C11: 283-876-4322 | D11: 500 Pacific Ave, Dallas, TX 75202 | E11: =IF(F11 < TODAY(), "❌ CDL EXPIRED", IF(G11 < TODAY(), "❌ MED CARD EXPIRED", IF(COUNTIFS(Assets!$B$2:$B$26, B11, Assets!$E$2:$E$26, "🔴 EXPIRED")>0, "❌ TRUCK NEEDS SERVICE", "✅ COMPLIANT"))) | F11: 45826 | G11: 46394 | H11: =RANDBETWEEN(DATE(2027,3,1),DATE(2027,4,7)) | I11: {=_xlfn.TEXTJOIN(", ", TRUE, _xlfn._xlws.FILTER(Assets!$A$2:$A$26, Assets!$B$2:$B$26 = A11, "No Truck Assigned"))}
A12: Driver 7 | B12: Sofia Gomez | C12: 896-828-7164 | D12: 815 Prospect Ave, Cleveland, OH 44115 | E12: =IF(F12 < TODAY(), "❌ CDL EXPIRED", IF(G12 < TODAY(), "❌ MED CARD EXPIRED", IF(COUNTIFS(Assets!$B$2:$B$26, B12, Assets!$E$2:$E$26, "🔴 EXPIRED")>0, "❌ TRUCK NEEDS SERVICE", "✅ COMPLIANT"))) | F12: 46530 | G12: 45739 | H12: =RANDBETWEEN(DATE(2027,3,1),DATE(2027,4,7)) | I12: {=_xlfn.TEXTJOIN(", ", TRUE, _xlfn._xlws.FILTER(Assets!$A$2:$A$26, Assets!$B$2:$B$26 = A12, "No Truck Assigned"))}
A13: Driver 8 | B13: Liam Smith | C13: 820-223-4829 | D13: 240 Madison Ave, Toledo, OH 43604 | E13: =IF(F13 < TODAY(), "❌ CDL EXPIRED", IF(G13 < TODAY(), "❌ MED CARD EXPIRED", IF(COUNTIFS(Assets!$B$2:$B$26, B13, Assets!$E$2:$E$26, "🔴 EXPIRED")>0, "❌ TRUCK NEEDS SERVICE", "✅ COMPLIANT"))) | F13: 46620 | G13: 46670 | H13: =RANDBETWEEN(DATE(2027,3,1),DATE(2027,4,7)) | I13: {=_xlfn.TEXTJOIN(", ", TRUE, _xlfn._xlws.FILTER(Assets!$A$2:$A$26, Assets!$B$2:$B$26 = A13, "No Truck Assigned"))}
A14: Driver 9 | B14: Emma Brown | C14: 206-700-7666 | D14: 330 Civic Center Dr, Columbus, OH 43215 | E14: =IF(F14 < TODAY(), "❌ CDL EXPIRED", IF(G14 < TODAY(), "❌ MED CARD EXPIRED", IF(COUNTIFS(Assets!$B$2:$B$26, B14, Assets!$E$2:$E$26, "🔴 EXPIRED")>0, "❌ TRUCK NEEDS SERVICE", "✅ COMPLIANT"))) | F14: 46424 | G14: 46645 | H14: =RANDBETWEEN(DATE(2027,3,1),DATE(2027,4,7)) | I14: {=_xlfn.TEXTJOIN(", ", TRUE, _xlfn._xlws.FILTER(Assets!$A$2:$A$26, Assets!$B$2:$B$26 = A14, "No Truck Assigned"))}
A15: Driver 10 | B15: Noah Wilson | C15: 582-987-2387 | D15: 110 W Adams St, Chicago, IL 60603 | E15: =IF(F15 < TODAY(), "❌ CDL EXPIRED", IF(G15 < TODAY(), "❌ MED CARD EXPIRED", IF(COUNTIFS(Assets!$B$2:$B$26, B15, Assets!$E$2:$E$26, "🔴 EXPIRED")>0, "❌ TRUCK NEEDS SERVICE", "✅ COMPLIANT"))) | F15: 46647 | G15: 46752 | H15: =RANDBETWEEN(DATE(2027,3,1),DATE(2027,4,7)) | I15: {=_xlfn.TEXTJOIN(", ", TRUE, _xlfn._xlws.FILTER(Assets!$A$2:$A$26, Assets!$B$2:$B$26 = A15, "No Truck Assigned"))}
A16: Driver 11 | B16: Olivia Lee | C16: 337-857-3607 | D16: 600 Peachtree St, Atlanta, GA 30308 | E16: =IF(F16 < TODAY(), "❌ CDL EXPIRED", IF(G16 < TODAY(), "❌ MED CARD EXPIRED", IF(COUNTIFS(Assets!$B$2:$B$26, B16, Assets!$E$2:$E$26, "🔴 EXPIRED")>0, "❌ TRUCK NEEDS SERVICE", "✅ COMPLIANT"))) | F16: 46566 | G16: 46499 | H16: =RANDBETWEEN(DATE(2027,3,1),DATE(2027,4,7)) | I16: {=_xlfn.TEXTJOIN(", ", TRUE, _xlfn._xlws.FILTER(Assets!$A$2:$A$26, Assets!$B$2:$B$26 = A16, "No Truck Assigned"))}

Sheet Documents
A1: Driver ID | B1: Full Name | C1: Phone | D1: Address | E1: Compliance Status | F1: Document Type | G1: Expiration Date | H1: File Link
A2: DRV-001 | B2: John Carter | C2: 206-667-3424 | D2: 1240 W 6th St, Cleveland, OH | E2: NON-COMPLIANT | F2: CDL Summary | G2: 46259 | H2: Link
A3: DRV-001 | B3: John Carter | C3: 206-667-3424 | D3: 1240 W 6th St, Cleveland, OH | E3: NON-COMPLIANT | F3: Medical Certification Summary | G3: 46029 | H3: Link
A4: DRV-001 | B4: John Carter | C4: 206-667-3424 | D4: 1240 W 6th St, Cleveland, OH | E4: NON-COMPLIANT | F4: MVR Summary | G4: 46037 | H4: Link
A5: DRV-001 | B5: John Carter | C5: 206-667-3424 | D5: 1240 W 6th St, Cleveland, OH | E5: NON-COMPLIANT | F5: Employment Eligibility Summary | G5: 46104 | H5: Link
A6: DRV-001 | B6: John Carter | C6: 206-667-3424 | D6: 1240 W 6th St, Cleveland, OH | E6: NON-COMPLIANT | F6: FMCSA Compliance Summary | G6: 45978 | H6: Link
A7: DRV-001 | B7: John Carter | C7: 206-667-3424 | D7: 1240 W 6th St, Cleveland, OH | E7: NON-COMPLIANT | F7: W-9 Summary | G7: 46190 | H7: Link
A8: DRV-001 | B8: John Carter | C8: 206-667-3424 | D8: 1240 W 6th St, Cleveland, OH | E8: NON-COMPLIANT | F8: Bank Information Sheet | G8: 46074 | H8: Link
A9: DRV-002 | B9: Maria Lopez | C9: 707-773-6386 | D9: 450 N Michigan Ave, Chicago, IL | E9: NON-COMPLIANT | F9: Medical Certification Summary | G9: 46264 | H9: Link
A10: DRV-002 | B10: Maria Lopez | C10: 707-773-6386 | D10: 450 N Michigan Ave, Chicago, IL | E10: NON-COMPLIANT | F10: Medical Certification Summary | G10: 46264 | H10: Link
A11: DRV-002 | B11: Maria Lopez | C11: 707-773-6386 | D11: 450 N Michigan Ave, Chicago, IL | E11: NON-COMPLIANT | F11: MVR Summary | G11: 46037 | H11: Link
A12: DRV-002 | B12: Maria Lopez | C12: 707-773-6386 | D12: 450 N Michigan Ave, Chicago, IL | E12: NON-COMPLIANT | F12: Employment Eligibility Summary | G12: 46049 | H12: Link
A13: DRV-002 | B13: Maria Lopez | C13: 707-773-6386 | D13: 450 N Michigan Ave, Chicago, IL | E13: NON-COMPLIANT | F13: FMCSA Compliance Summary | G13: 46182 | H13: Link
... A85: DRV-012 | B85: Robert Johnson | C85: 618-623-9317 | D85: 88 S Main St, Akron, OH | E85: VALID | F85: Bank Information Sheet | G85: 46069 | H85: Link

Sheet Assets
A1: Asset ID | B1: Assigned Driver | C1: Last Service Date | D1: Next Service Date | E1: Status Indicator
A2: T-101 | B2: Driver 12 | C2: 45777 | D2: 46119 | E2: =IF(D2 < TODAY(), "🔴 EXPIRED", IF(D2 <= TODAY()+30, "🟡 DUE SOON", "🟢 OK"))
A3: T-102 | B3: Driver 1 | C3: 46011 | D3: 46067 | E3: =IF(D3 < TODAY(), "🔴 EXPIRED", IF(D3 <= TODAY()+30, "🟡 DUE SOON", "🟢 OK"))
A4: T-103 | B4: Driver 6 | C4: 45781 | D4: 46095 | E4: =IF(D4 < TODAY(), "🔴 EXPIRED", IF(D4 <= TODAY()+30, "🟡 DUE SOON", "🟢 OK"))
A5: T-104 | B5: Driver 5 | C5: 45726 | D5: 46077 | E5: =IF(D5 < TODAY(), "🔴 EXPIRED", IF(D5 <= TODAY()+30, "🟡 DUE SOON", "🟢 OK"))
A6: T-105 | B6: Driver 10 | C6: 45747 | D6: 46165 | E6: =IF(D6 < TODAY(), "🔴 EXPIRED", IF(D6 <= TODAY()+30, "🟡 DUE SOON", "🟢 OK"))
A7: T-106 | B7: Driver 8 | C7: 45662 | D7: 46105 | E7: =IF(D7 < TODAY(), "🔴 EXPIRED", IF(D7 <= TODAY()+30, "🟡 DUE SOON", "🟢 OK"))
A8: T-107 | B8: Driver 3 | C8: 45821 | D8: 46067 | E8: =IF(D8 < TODAY(), "🔴 EXPIRED", IF(D8 <= TODAY()+30, "🟡 DUE SOON", "🟢 OK"))
A9: T-108 | B9: Driver 4 | C9: 45764 | D9: 46127 | E9: =IF(D9 < TODAY(), "🔴 EXPIRED", IF(D9 <= TODAY()+30, "🟡 DUE SOON", "🟢 OK"))
A10: T-109 | B10: Driver 9 | C10: 45879 | D10: 46062 | E10: =IF(D10 < TODAY(), "🔴 EXPIRED", IF(D10 <= TODAY()+30, "🟡 DUE SOON", "🟢 OK"))
A11: T-110 | B11: Driver 4 | C11: 45997 | D11: 46096 | E11: =IF(D11 < TODAY(), "🔴 EXPIRED", IF(D11 <= TODAY()+30, "🟡 DUE SOON", "🟢 OK"))
A12: T-111 | B12: Driver 7 | C12: 46012 | D12: 46158 | E12: =IF(D12 < TODAY(), "🔴 EXPIRED", IF(D12 <= TODAY()+30, "🟡 DUE SOON", "🟢 OK"))
A13: T-112 | B13: Driver 5 | C13: 46021 | D13: 46171 | E13: =IF(D13 < TODAY(), "🔴 EXPIRED", IF(D13 <= TODAY()+30, "🟡 DUE SOON", "🟢 OK"))
... A26: T-125 | B26: Driver 2 | C26: 45773 | D26: 46084 | E26: =IF(D26 < TODAY(), "🔴 EXPIRED", IF(D26 <= TODAY()+30, "🟡 DUE SOON", "🟢 OK"))

Sheet Maintenance

Sheet Dispatch
A1: Load ID | B1: Driver ID | C1: Asset ID | D1: Revenue | E1: Backhaul Pay | F1: Driver Signature? | G1: Load Status | H1: Reason for Pending Status | I1: Seal Number (Pickup) | J1: Seal Photo (Pickup) | K1: Seal Number (Delivery) | L1: Seal Photo (Delivery) | M1: Seal Status | N1: Exception Flag | O1: Override Reason | P1: Audit Log | Q1: Compliance Lock
A2: L-501 | B2: Driver 1 | C2: T-102 | D2: 2000 | E2: 65 | F2: No | G2: Delivered | I2: SEAL-83921 | J2: pickup_photo_01.jpg | K2: SEAL-83920 | L2: delivery_photo_01.jpg | M2: =IF(K2="","Pending",IF(K2<>I2,"Mismatch","Verified")) | N2: =IF(M2="Mismatch","SEAL MISMATCH","") | P2: =IF(M2="Mismatch","Seal mismatch detected. Pickup: "&I2&" Delivery: "&K2&" | Override: "&IF(O2="","None",O2),"") | Q2: =IF(N2="SEAL MISMATCH",IF(O2="","LOCKED","OVERRIDDEN"),"CLEAR")
A3: L-502 | B3: Driver 2 | C3: T-101 | D3: 1800 | E3: 95 | F3: No | G3: In-Transit | I3: SEAL-55219 | J3: pickup_photo_02.jpg | K3: SEAL-55219 | L3: delivery_photo_02.jpg | M3: =IF(K3="","Pending",IF(K3<>I3,"Mismatch","Verified")) | N3: =IF(M3="Mismatch","SEAL MISMATCH","") | P3: =IF(M3="Mismatch","Seal mismatch detected. Pickup: "&I3&" Delivery: "&K3&" | Override: "&IF(O3="","None",O3),"") | Q3: =IF(N3="SEAL MISMATCH",IF(O3="","LOCKED","OVERRIDDEN"),"CLEAR")
A4: L-503 | B4: Driver 3 | C4: T-107 | D4: 2100 | E4: 45 | F4: No | G4: Delivered | I4: SEAL-77102 | J4: pickup_photo_03.jpg | M4: =IF(K4="","Pending",IF(K4<>I4,"Mismatch","Verified")) | N4: =IF(M4="Mismatch","SEAL MISMATCH","") | P4: =IF(M4="Mismatch","Seal mismatch detected. Pickup: "&I4&" Delivery: "&K4&" | Override: "&IF(O4="","None",O4),"") | Q4: =IF(N4="SEAL MISMATCH",IF(O4="","LOCKED","OVERRIDDEN"),"CLEAR")
A5: L-504 | B5: Driver 4 | C5: T-108 | D5: 1950 | E5: 88 | F5: Yes | G5: Pending | H5: Awaiting POD | I5: SEAL-61044 | J5: pickup_photo_04.jpg | K5: SEAL-61043 | L5: delivery_photo_04.jpg | M5: =IF(K5="","Pending",IF(K5<>I5,"Mismatch","Verified")) | N5: =IF(M5="Mismatch","SEAL MISMATCH","") | O5: Dock supervisor approved | P5: =IF(M5="Mismatch","Seal mismatch detected. Pickup: "&I5&" Delivery: "&K5&" | Override: "&IF(O5="","None",O5),"") | Q5: =IF(N5="SEAL MISMATCH",IF(O5="","LOCKED","OVERRIDDEN"),"CLEAR")
A6: L-505 | B6: Driver 5 | C6: T-104 | D6: 2200 | E6: 45 | F6: No | G6: Delivered | I6: SEAL-44018 | J6: pickup_photo_05.jpg | K6: SEAL-44018 | L6: delivery_photo_05.jpg | M6: =IF(K6="","Pending",IF(K6<>I6,"Mismatch","Verified")) | N6: =IF(M6="Mismatch","SEAL MISMATCH","") | P6: =IF(M6="Mismatch","Seal mismatch detected. Pickup: "&I6&" Delivery: "&K6&" | Override: "&IF(O6="","None",O6),"") | Q6: =IF(N6="SEAL MISMATCH",IF(O6="","LOCKED","OVERRIDDEN"),"CLEAR")
A7: L-506 | B7: Driver 6 | C7: T-103 | D7: 2050 | E7: 72 | F7: Yes | G7: Delivered | I7: SEAL-99871 | J7: pickup_photo_06.jpg | M7: =IF(K7="","Pending",IF(K7<>I7,"Mismatch","Verified")) | N7: =IF(M7="Mismatch","SEAL MISMATCH","") | P7: =IF(M7="Mismatch","Seal mismatch detected. Pickup: "&I7&" Delivery: "&K7&" | Override: "&IF(O7="","None",O7),"") | Q7: =IF(N7="SEAL MISMATCH",IF(O7="","LOCKED","OVERRIDDEN"),"CLEAR")
A8: L-507 | B8: Driver 7 | C8: T-109 | D8: 2300 | E8: 58 | F8: No | G8: In-Transit | I8: SEAL-73005 | J8: pickup_photo_07.jpg | K8: SEAL-73099 | L8: delivery_photo_07.jpg | M8: =IF(K8="","Pending",IF(K8<>I8,"Mismatch","Verified")) | N8: =IF(M8="Mismatch","SEAL MISMATCH","") | P8: =IF(M8="Mismatch","Seal mismatch detected. Pickup: "&I8&" Delivery: "&K8&" | Override: "&IF(O8="","None",O8),"") | Q8: =IF(N8="SEAL MISMATCH",IF(O8="","LOCKED","OVERRIDDEN"),"CLEAR")
A9: L-508 | B9: Driver 8 | C9: T-110 | D9: 1750 | E9: 81 | F9: Yes | G9: Delivered | I9: SEAL-18542 | J9: pickup_photo_08.jpg | K9: SEAL-18542 | L9: delivery_photo_08.jpg | M9: =IF(K9="","Pending",IF(K9<>I9,"Mismatch","Verified")) | N9: =IF(M9="Mismatch","SEAL MISMATCH","") | P9: =IF(M9="Mismatch","Seal mismatch detected. Pickup: "&I9&" Delivery: "&K9&" | Override: "&IF(O9="","None",O9),"") | Q9: =IF(N9="SEAL MISMATCH",IF(O9="","LOCKED","OVERRIDDEN"),"CLEAR")
A10: L-509 | B10: Driver 9 | C10: T-111 | D10: 2400 | E10: 49 | F10: No | G10: Pending | H10: Customer hold | I10: SEAL-26790 | J10: pickup_photo_09.jpg | K10: SEAL-26791 | L10: delivery_photo_09.jpg | M10: =IF(K10="","Pending",IF(K10<>I10,"Mismatch","Verified")) | N10: =IF(M10="Mismatch","SEAL MISMATCH","") | O10: Carrier note logged | P10: =IF(M10="Mismatch","Seal mismatch detected. Pickup: "&I10&" Delivery: "&K10&" | Override: "&IF(O10="","None",O10),"") | Q10: =IF(N10="SEAL MISMATCH",IF(O10="","LOCKED","OVERRIDDEN"),"CLEAR")
A11: L-510 | B11: Driver 10 | C11: T-105 | D11: 1900 | E11: 77 | F11: Yes | G11: Delivered | I11: SEAL-48113 | J11: pickup_photo_10.jpg | M11: =IF(K11="","Pending",IF(K11<>I11,"Mismatch","Verified")) | N11: =IF(M11="Mismatch","SEAL MISMATCH","") | P11: =IF(M11="Mismatch","Seal mismatch detected. Pickup: "&I11&" Delivery: "&K11&" | Override: "&IF(O11="","None",O11),"") | Q11: =IF(N11="SEAL MISMATCH",IF(O11="","LOCKED","OVERRIDDEN"),"CLEAR")
A12: L-511 | B12: Driver 11 | C12: T-112 | D12: 2250 | E12: 63 | F12: No | G12: In-Transit | I12: SEAL-91420 | J12: pickup_photo_11.jpg | K12: SEAL-91420 | L12: delivery_photo_11.jpg | M12: =IF(K12="","Pending",IF(K12<>I12,"Mismatch","Verified")) | N12: =IF(M12="Mismatch","SEAL MISMATCH","") | P12: =IF(M12="Mismatch","Seal mismatch detected. Pickup: "&I12&" Delivery: "&K12&" | Override: "&IF(O12="","None",O12),"") | Q12: =IF(N12="SEAL MISMATCH",IF(O12="","LOCKED","OVERRIDDEN"),"CLEAR")
A13: L-512 | B13: Driver 12 | C13: T-106 | D13: 2150 | E13: 69 | F13: Yes | G13: Delivered | I13: SEAL-35864 | J13: pickup_photo_12.jpg | K13: SEAL-35860 | L13: delivery_photo_12.jpg | M13: =IF(K13="","Pending",IF(K13<>I13,"Mismatch","Verified")) | N13: =IF(M13="Mismatch","SEAL MISMATCH","") | P13: =IF(M13="Mismatch","Seal mismatch detected. Pickup: "&I13&" Delivery: "&K13&" | Override: "&IF(O13="","None",O13),"") | Q13: =IF(N13="SEAL MISMATCH",IF(O13="","LOCKED","OVERRIDDEN"),"CLEAR")

Sheet Dashboard
A1: Compliance Monitoring Dashboard
A2: Updated to reference Dispatch and all cells are editable
A4: Total Loads | B4: =COUNTA(Dispatch!$A$2:$A$1000)
A5: Verified | B5: =COUNTIF(Dispatch!$M$2:$M$1000,"Verified")
A6: Mismatch | B6: =COUNTIF(Dispatch!$M$2:$M$1000,"Mismatch")
A7: Pending | B7: =COUNTIF(Dispatch!$M$2:$M$1000,"Pending")
A8: Locked | B8: =COUNTIF(Dispatch!$Q$2:$Q$1000,"LOCKED")
A9: Overrides | B9: =COUNTIF(Dispatch!$Q$2:$Q$1000,"OVERRIDDEN")
A10: Compliance % | B10: =IF(B4=0,0,B5/B4)
A13: Driver ID | B13: Deal Count | C13: Revenue | D13: Compliance % | E13: Locked
A14: Driver 1 | B14: =COUNTIF(Dispatch!$B$2:$B$1000,A14) | C14: =SUMIF(Dispatch!$B$2:$B$1000,A14,Dispatch!$D$2:$D$1000) | D14: =IF(B14=0,0,COUNTIFS(Dispatch!$B$2:$B$1000,A14,Dispatch!$M$2:$M$1000,"Verified")/B14) | E14: =COUNTIFS(Dispatch!$B$2:$B$1000,A14,Dispatch!$Q$2:$Q$1000,"LOCKED")
A15: Driver 2 | B15: =COUNTIF(Dispatch!$B$2:$B$1000,A15) | C15: =SUMIF(Dispatch!$B$2:$B$1000,A15,Dispatch!$D$2:$D$1000) | D15: =IF(B15=0,0,COUNTIFS(Dispatch!$B$2:$B$1000,A15,Dispatch!$M$2:$M$1000,"Verified")/B15) | E15: =COUNTIFS(Dispatch!$B$2:$B$1000,A15,Dispatch!$Q$2:$Q$1000,"LOCKED")
A16: Driver 3 | B16: =COUNTIF(Dispatch!$B$2:$B$1000,A16) | C16: =SUMIF(Dispatch!$B$2:$B$1000,A16,Dispatch!$D$2:$D$1000) | D16: =IF(B16=0,0,COUNTIFS(Dispatch!$B$2:$B$1000,A16,Dispatch!$M$2:$M$1000,"Verified")/B16) | E16: =COUNTIFS(Dispatch!$B$2:$B$1000,A16,Dispatch!$Q$2:$Q$1000,"LOCKED")
A17: Driver 4 | B17: =COUNTIF(Dispatch!$B$2:$B$1000,A17) | C17: =SUMIF(Dispatch!$B$2:$B$1000,A17,Dispatch!$D$2:$D$1000) | D17: =IF(B17=0,0,COUNTIFS(Dispatch!$B$2:$B$1000,A17,Dispatch!$M$2:$M$1000,"Verified")/B17) | E17: =COUNTIFS(Dispatch!$B$2:$B$1000,A17,Dispatch!$Q$2:$Q$1000,"LOCKED")
A18: Driver 5 | B18: =COUNTIF(Dispatch!$B$2:$B$1000,A18) | C18: =SUMIF(Dispatch!$B$2:$B$1000,A18,Dispatch!$D$2:$D$1000) | D18: =IF(B18=0,0,COUNTIFS(Dispatch!$B$2:$B$1000,A18,Dispatch!$M$2:$M$1000,"Verified")/B18) | E18: =COUNTIFS(Dispatch!$B$2:$B$1000,A18,Dispatch!$Q$2:$Q$1000,"LOCKED")
A19: Driver 6 | B19: =COUNTIF(Dispatch!$B$2:$B$1000,A19) | C19: =SUMIF(Dispatch!$B$2:$B$1000,A19,Dispatch!$D$2:$D$1000) | D19: =IF(B19=0,0,COUNTIFS(Dispatch!$B$2:$B$1000,A19,Dispatch!$M$2:$M$1000,"Verified")/B19) | E19: =COUNTIFS(Dispatch!$B$2:$B$1000,A19,Dispatch!$Q$2:$Q$1000,"LOCKED")
A20: Driver 7 | B20: =COUNTIF(Dispatch!$B$2:$B$1000,A20) | C20: =SUMIF(Dispatch!$B$2:$B$1000,A20,Dispatch!$D$2:$D$1000) | D20: =IF(B20=0,0,COUNTIFS(Dispatch!$B$2:$B$1000,A20,Dispatch!$M$2:$M$1000,"Verified")/B20) | E20: =COUNTIFS(Dispatch!$B$2:$B$1000,A20,Dispatch!$Q$2:$Q$1000,"LOCKED")
A21: Driver 8 | B21: =COUNTIF(Dispatch!$B$2:$B$1000,A21) | C21: =SUMIF(Dispatch!$B$2:$B$1000,A21,Dispatch!$D$2:$D$1000) | D21: =IF(B21=0,0,COUNTIFS(Dispatch!$B$2:$B$1000,A21,Dispatch!$M$2:$M$1000,"Verified")/B21) | E21: =COUNTIFS(Dispatch!$B$2:$B$1000,A21,Dispatch!$Q$2:$Q$1000,"LOCKED")
A22: Driver 9 | B22: =COUNTIF(Dispatch!$B$2:$B$1000,A22) | C22: =SUMIF(Dispatch!$B$2:$B$1000,A22,Dispatch!$D$2:$D$1000) | D22: =IF(B22=0,0,COUNTIFS(Dispatch!$B$2:$B$1000,A22,Dispatch!$M$2:$M$1000,"Verified")/B22) | E22: =COUNTIFS(Dispatch!$B$2:$B$1000,A22,Dispatch!$Q$2:$Q$1000,"LOCKED")
A23: Driver 10 | B23: =COUNTIF(Dispatch!$B$2:$B$1000,A23) | C23: =SUMIF(Dispatch!$B$2:$B$1000,A23,Dispatch!$D$2:$D$1000) | D23: =IF(B23=0,0,COUNTIFS(Dispatch!$B$2:$B$1000,A23,Dispatch!$M$2:$M$1000,"Verified")/B23) | E23: =COUNTIFS(Dispatch!$B$2:$B$1000,A23,Dispatch!$Q$2:$Q$1000,"LOCKED")
A24: Driver 11 | B24: =COUNTIF(Dispatch!$B$2:$B$1000,A24) | C24: =SUMIF(Dispatch!$B$2:$B$1000,A24,Dispatch!$D$2:$D$1000) | D24: =IF(B24=0,0,COUNTIFS(Dispatch!$B$2:$B$1000,A24,Dispatch!$M$2:$M$1000,"Verified")/B24) | E24: =COUNTIFS(Dispatch!$B$2:$B$1000,A24,Dispatch!$Q$2:$Q$1000,"LOCKED")
A25: Driver 12 | B25: =COUNTIF(Dispatch!$B$2:$B$1000,A25) | C25: =SUMIF(Dispatch!$B$2:$B$1000,A25,Dispatch!$D$2:$D$1000) | D25: =IF(B25=0,0,COUNTIFS(Dispatch!$B$2:$B$1000,A25,Dispatch!$M$2:$M$1000,"Verified")/B25) | E25: =COUNTIFS(Dispatch!$B$2:$B$1000,A25,Dispatch!$Q$2:$Q$1000,"LOCKED")

Sheet Payroll
A1: Driver | B1: Base Earnings | C1: Backhaul Pay | D1: Gross Pay | E1: FICA | F1: OASDI | G1: Federal Withholding | H1: State Withholding | I1: SDI | J1: FM Leave | K1: Family Support | L1: Insurance Premiums | M1: Credit Union Savings Club | N1: 401(k) Contribution | O1: HSA/FSA Health Deduction | P1: Health Insurance Premiums | Q1: Life Insurance Above 50k | R1: Total Deductions | S1: Fuel Reimb. | T1: Net Pay | U1: Status | V1: Pending Reason | W1: 401(k) Rate
A2: J. Carter | B2: 2100 | C2: 65 | D2: =B2+C2 | E2: =0.062*D2 | F2: =0.0145*D2 | G2: =0.18*D2 | H2: =0.035*D2 | I2: =0.0045*D2 | J2: =0.0066*D2 | K2: 0 | L2: 214.92 | M2: 0 | N2: =D2*W2 | O2: 114.79 | P2: 0 | Q2: 0 | R2: =D2-E2-F2-G2-H2-I2-J2-K2-L2-M2-N2-O2-P2-Q2 | S2: 0 | T2: =D2-R2 | U2: Paid | V2: N/A | W2: 0.03
A3: M. Lopez | B3: 1910 | C3: 95 | D3: =B3+C3 | E3: =0.062*D3 | F3: =0.0145*D3 | G3: =0.18*D3 | H3: =0.035*D3 | I3: =0.0045*D3 | J3: =0.0066*D3 | K3: 79.68 | L3: 0 | M3: 42.09 | N3: =D3*W3 | O3: 69.33 | P3: 0 | Q3: 0 | R3: =D3-E3-F3-G3-H3-I3-J3-K3-L3-M3-N3-O3-P3-Q3 | S3: 120 | T3: =D3-R3 | U3: Pending | V3: Awaiting Receipts | W3: 0
A4: A. Kim | B4: 2155 | C4: 45 | D4: =B4+C4 | E4: =0.062*D4 | F4: =0.0145*D4 | G4: =0.18*D4 | H4: =0.035*D4 | I4: =0.0045*D4 | J4: =0.0066*D4 | K4: 0 | L4: 0 | M4: 30.98 | N4: =D4*W4 | O4: 0 | P4: 0 | Q4: 0 | R4: =D4-E4-F4-G4-H4-I4-J4-K4-L4-M4-N4-O4-P4-Q4 | S4: 0 | T4: =D4-R4 | U4: Paid | V4: N/A | W4: 0.06
A5: P. Patel | B5: 2020 | C5: 88 | D5: =B5+C5 | E5: =0.062*D5 | F5: =0.0145*D5 | G5: =0.18*D5 | H5: =0.035*D5 | I5: =0.0045*D5 | J5: =0.0066*D5 | K5: 0 | L5: 0 | M5: 32.58 | N5: =D5*W5 | O5: 0 | P5: 0 | Q5: 0 | R5: =D5-E5-F5-G5-H5-I5-J5-K5-L5-M5-N5-O5-P5-Q5 | S5: 150 | T5: =D5-R5 | U5: Pending | V5: Awaiting Receipts | W5: 0
A6: K. Tanaka | B6: 2280 | C6: 45 | D6: =B6+C6 | E6: =0.062*D6 | F6: =0.0145*D6 | G6: =0.18*D6 | H6: =0.035*D6 | I6: =0.0045*D6 | J6: =0.0066*D6 | K6: 187.05 | L6: 0 | M6: 72.68 | N6: =D6*W6 | O6: 26.5 | P6: 0 | Q6: 0 | R6: =D6-E6-F6-G6-H6-I6-J6-K6-L6-M6-N6-O6-P6-Q6 | S6: 0 | T6: =D6-R6 | U6: Pending | V6: Load Verification | W6: 0.03
A7: M. Chen | B7: 2090 | C7: 72 | D7: =B7+C7 | E7: =0.062*D7 | F7: =0.0145*D7 | G7: =0.18*D7 | H7: =0.035*D7 | I7: =0.0045*D7 | J7: =0.0066*D7 | K7: 0 | L7: 0 | M7: 0 | N7: =D7*W7 | O7: 0 | P7: 0 | Q7: 24.94 | R7: =D7-E7-F7-G7-H7-I7-J7-K7-L7-M7-N7-O7-P7-Q7 | S7: 0 | T7: =D7-R7 | U7: Paid | V7: N/A | W7: 0.03
A8: S. Gomez | B8: 1975 | C8: 58 | D8: =B8+C8 | E8: =0.062*D8 | F8: =0.0145*D8 | G8: =0.18*D8 | H8: =0.035*D8 | I8: =0.0045*D8 | J8: =0.0066*D8 | K8: 246.6 | L8: 146.97 | M8: 0 | N8: =D8*W8 | O8: 0 | P8: 0 | Q8: 7.04 | R8: =D8-E8-F8-G8-H8-I8-J8-K8-L8-M8-N8-O8-P8-Q8 | S8: 0 | T8: =D8-R8 | U8: Paid | V8: N/A | W8: 0.05
A9: L. Smith | B9: 2165 | C9: 81 | D9: =B9+C9 | E9: =0.062*D9 | F9: =0.0145*D9 | G9: =0.18*D9 | H9: =0.035*D9 | I9: =0.0045*D9 | J9: =0.0066*D9 | K9: 0 | L9: 0 | M9: 45.02 | N9: =D9*W9 | O9: 0 | P9: 111.66 | Q9: 0 | R9: =D9-E9-F9-G9-H9-I9-J9-K9-L9-M9-N9-O9-P9-Q9 | S9: 0 | T9: =D9-R9 | U9: Pending | V9: Load Verification | W9: 0
A10: E. Brown | B10: 2110 | C10: 49 | D10: =B10+C10 | E10: =0.062*D10 | F10: =0.0145*D10 | G10: =0.18*D10 | H10: =0.035*D10 | I10: =0.0045*D10 | J10: =0.0066*D10 | K10: 67.76 | L10: 0 | M10: 0 | N10: =D10*W10 | O10: 24.17 | P10: 0 | Q10: 0 | R10: =D10-E10-F10-G10-H10-I10-J10-K10-L10-M10-N10-O10-P10-Q10 | S10: 0 | T10: =D10-R10 | U10: Paid | V10: N/A | W10: 0
A11: N. Wilson | B11: 2080 | C11: 77 | D11: =B11+C11 | E11: =0.062*D11 | F11: =0.0145*D11 | G11: =0.18*D11 | H11: =0.035*D11 | I11: =0.0045*D11 | J11: =0.0066*D11 | K11: 0 | L11: 0 | M11: 0 | N11: =D11*W11 | O11: 0 | P11: 196.15 | Q11: 0 | R11: =D11-E11-F11-G11-H11-I11-J11-K11-L11-M11-N11-O11-P11-Q11 | S11: 0 | T11: =D11-R11 | U11: Paid | V11: N/A | W11: 0.02
A12: O. Lee | B12: 2010 | C12: 63 | D12: =B12+C12 | E12: =0.062*D12 | F12: =0.0145*D12 | G12: =0.18*D12 | H12: =0.035*D12 | I12: =0.0045*D12 | J12: =0.0066*D12 | K12: 50.51 | L12: 0 | M12: 0 | N12: =D12*W12 | O12: 47.43 | P12: 0 | Q12: 0 | R12: =D12-E12-F12-G12-H12-I12-J12-K12-L12-M12-N12-O12-P12-Q12 | S12: 0 | T12: =D12-R12 | U12: Paid | V12: N/A | W12: 0

Sheet Payroll Summary
A1: Metric | B1: Total
A2: Total Base Earnings | B2: =SUM(Payroll!B2:B12)
A3: Total Backhaul Pay | B3: =SUM(Payroll!C2:C12)
A4: Total Gross Pay | B4: =SUM(Payroll!D2:D12)
A5: Total FICA | B5: =SUM(Payroll!E2:E12)
A6: Total OASDI | B6: =SUM(Payroll!F2:F12)
A7: Total Federal Withholding | B7: =SUM(Payroll!G2:G12)
A8: Total State Withholding | B8: =SUM(Payroll!H2:H12)
A9: Total SDI | B9: =SUM(Payroll!I2:I12)
A10: Total FM Leave | B10: =SUM(Payroll!J2:J12)
A11: Total Family Support | B11: =SUM(Payroll!K2:K12)
A12: Total Insurance Premiums | B12: =SUM(Payroll!L2:L12)
A13: Total Credit Union Savings Club | B13: =SUM(Payroll!M2:M12)
A14: Total 401(k) Contribution | B14: =SUM(Payroll!N2:N12)
A15: Total HSA/FSA Health Deduction | B15: =SUM(Payroll!O2:O12)
A16: Total Health Insurance Premiums | B16: =SUM(Payroll!P2:P12)
A17: Total Life Insurance Above 50k | B17: =SUM(Payroll!Q2:Q12)
A18: Total Deductions | B18: =SUM(Payroll!S2:S12)
A19: Total Fuel Reimb. | B19: =SUM(Payroll!T2:T12)
A20: Total Net Pay | B20: =SUM(Payroll!U2:U12)

Sheet Drivers_Clean
A1: Legacy Driver ID | B1: Driver ID | C1: Full Name | D1: Phone Number | E1: Address | F1: CDL Expiration Date | G1: Medical Card Expiration | H1: MVR Expiration | I1: Assigned Truck | J1: Compliance Status | K1: Photo URL | L1: CDL URL | M1: MVR URL | N1: Medical URL | O1: Compliance Tier | P1: Primary Truck | Q1: W9 URL | R1: I9 URL | S1: FMCSA URL | T1: Bank Info URL | U1: Driver Folder URL
A2: Driver 1 | B2: DRV-001 | C2: John Carter | D2: 206-667-3424 | E2: 1240 W 6th St, Cleveland, OH 44113 | F2: 46621 | G2: 46094 | H2: 46080 | I2: T-102, T-121 | J2: ❌ MED CARD EXPIRED | MVR EXPIRED | TRUCK NEEDS SERVICE | K2: /drivers/DRV-001.jpg | L2: /documents/drivers/DRV-001_CDL.pdf | M2: /documents/drivers/DRV-001_MVR.pdf | N2: /documents/drivers/DRV-001_MEDICAL.pdf | O2: NON_COMPLIANT | P2: T-102 | Q2: /documents/drivers/DRV-001_W9.pdf | R2: /documents/drivers/DRV-001_I9.pdf | S2: /documents/drivers/DRV-001_FMCSA.pdf | T2: /documents/drivers/DRV-001_BANK_INFO.pdf | U2: /documents/drivers/DRV-001/
A3: Driver 2 | B3: DRV-002 | C3: Maria Lopez | D3: 707-773-6386 | E3: 450 N Michigan Ave, Chicago, IL 60611 | F3: 46518 | G3: 46596 | H3: 46465.5 | I3: T-122, T-124, T-125 | J3: ❌ TRUCK NEEDS SERVICE | K3: /drivers/DRV-002.jpg | L3: /documents/drivers/DRV-002_CDL.pdf | M3: /documents/drivers/DRV-002_MVR.pdf | N3: /documents/drivers/DRV-002_MEDICAL.pdf | O3: NON_COMPLIANT | P3: T-122 | Q3: /documents/drivers/DRV-002_W9.pdf | R3: /documents/drivers/DRV-002_I9.pdf | S3: /documents/drivers/DRV-002_FMCSA.pdf | T3: /documents/drivers/DRV-002_BANK_INFO.pdf | U3: /documents/drivers/DRV-002/
A4: Driver 3 | B4: DRV-003 | C4: Alex Kim | D4: 675-486-1335 | E4: 780 Peachtree St, Atlanta, GA 30308 | F4: 46420 | G4: 46659 | H4: 46465.5 | I4: T-107, T-123 | J4: ❌ TRUCK NEEDS SERVICE | K4: /drivers/DRV-003.jpg | L4: /documents/drivers/DRV-003_CDL.pdf | M4: /documents/drivers/DRV-003_MVR.pdf | N4: /documents/drivers/DRV-003_MEDICAL.pdf | O4: NON_COMPLIANT | P4: T-107 | Q4: /documents/drivers/DRV-003_W9.pdf | R4: /documents/drivers/DRV-003_I9.pdf | S4: /documents/drivers/DRV-003_FMCSA.pdf | T4: /documents/drivers/DRV-003_BANK_INFO.pdf | U4: /documents/drivers/DRV-003/
A5: Driver 4 | B5: DRV-004 | C5: Priya Patel | D5: 359-469-5960 | E5: 2200 Superior Ave, Cleveland, OH 44114 | F5: 46739 | G5: 46486 | H5: 46465.5 | I5: T-108, T-110, T-113, T-116 | J5: ❌ TRUCK NEEDS SERVICE | K5: /drivers/DRV-004.jpg | L5: /documents/drivers/DRV-004_CDL.pdf | M5: /documents/drivers/DRV-004_MVR.pdf | N5: /documents/drivers/DRV-004_MEDICAL.pdf | O5: NON_COMPLIANT | P5: T-108 | Q5: /documents/drivers/DRV-004_W9.pdf | R5: /documents/drivers/DRV-004_I9.pdf | S5: /documents/drivers/DRV-004_FMCSA.pdf | T5: /documents/drivers/DRV-004_BANK_INFO.pdf | U5: /documents/drivers/DRV-004/
A6: Driver 5 | B6: DRV-005 | C6: Kenji Tanaka | D6: 871-429-6220 | E6: 115 E Broad St, Columbus, OH 43215 | F6: 46577 | G6: 46496 | H6: 46465.5 | I6: T-104, T-112 | J6: ❌ TRUCK NEEDS SERVICE | K6: /drivers/DRV-005.jpg | L6: /documents/drivers/DRV-005_CDL.pdf | M6: /documents/drivers/DRV-005_MVR.pdf | N6: /documents/drivers/DRV-005_MEDICAL.pdf | O6: NON_COMPLIANT | P6: T-104 | Q6: /documents/drivers/DRV-005_W9.pdf | R6: /documents/drivers/DRV-005_I9.pdf | S6: /documents/drivers/DRV-005_FMCSA.pdf | T6: /documents/drivers/DRV-005_BANK_INFO.pdf | U6: /documents/drivers/DRV-005/
A7: Driver 6 | B7: DRV-006 | C7: Marcus Chen | D7: 283-876-4322 | E7: 500 Pacific Ave, Dallas, TX 75202 | F7: 45826 | G7: 46394 | H7: 46465.5 | I7: T-103, T-117, T-119 | J7: ❌ CDL EXPIRED | TRUCK NEEDS SERVICE | K7: /drivers/DRV-006.jpg | L7: /documents/drivers/DRV-006_CDL.pdf | M7: /documents/drivers/DRV-006_MVR.pdf | N7: /documents/drivers/DRV-006_MEDICAL.pdf | O7: NON_COMPLIANT | P7: T-103 | Q7: /documents/drivers/DRV-006_W9.pdf | R7: /documents/drivers/DRV-006_I9.pdf | S7: /documents/drivers/DRV-006_FMCSA.pdf | T7: /documents/drivers/DRV-006_BANK_INFO.pdf | U7: /documents/drivers/DRV-006/
A8: Driver 7 | B8: DRV-007 | C8: Sofia Gomez | D8: 896-828-7164 | E8: 815 Prospect Ave, Cleveland, OH 44115 | F8: 46530 | G8: 45739 | H8: 46465.5 | I8: T-111 | J8: ❌ MED CARD EXPIRED | K8: /drivers/DRV-007.jpg | L8: /documents/drivers/DRV-007_CDL.pdf | M8: /documents/drivers/DRV-007_MVR.pdf | N8: /documents/drivers/DRV-007_MEDICAL.pdf | O8: NON_COMPLIANT | P8: T-111 | Q8: /documents/drivers/DRV-007_W9.pdf | R8: /documents/drivers/DRV-007_I9.pdf | S8: /documents/drivers/DRV-007_FMCSA.pdf | T8: /documents/drivers/DRV-007_BANK_INFO.pdf | U8: /documents/drivers/DRV-007/
A9: Driver 8 | B9: DRV-008 | C9: Liam Smith | D9: 820-223-4829 | E9: 240 Madison Ave, Toledo, OH 43604 | F9: 46620 | G9: 46670 | H9: 46465.5 | I9: T-106, T-120 | J9: ❌ TRUCK NEEDS SERVICE | K9: /drivers/DRV-008.jpg | L9: /documents/drivers/DRV-008_CDL.pdf | M9: /documents/drivers/DRV-008_MVR.pdf | N9: /documents/drivers/DRV-008_MEDICAL.pdf | O9: NON_COMPLIANT | P9: T-106 | Q9: /documents/drivers/DRV-008_W9.pdf | R9: /documents/drivers/DRV-008_I9.pdf | S9: /documents/drivers/DRV-008_FMCSA.pdf | T9: /documents/drivers/DRV-008_BANK_INFO.pdf | U9: /documents/drivers/DRV-008/
A10: Driver 9 | B10: DRV-009 | C10: Emma Brown | D10: 206-700-7666 | E10: 330 Civic Center Dr, Columbus, OH 43215 | F10: 46424 | G10: 46645 | H10: 46465.5 | I10: T-109 | J10: ❌ TRUCK NEEDS SERVICE | K10: /drivers/DRV-009.jpg | L10: /documents/drivers/DRV-009_CDL.pdf | M10: /documents/drivers/DRV-009_MVR.pdf | N10: /documents/drivers/DRV-009_MEDICAL.pdf | O10: NON_COMPLIANT | P10: T-109 | Q10: /documents/drivers/DRV-009_W9.pdf | R10: /documents/drivers/DRV-009_I9.pdf | S10: /documents/drivers/DRV-009_FMCSA.pdf | T10: /documents/drivers/DRV-009_BANK_INFO.pdf | U10: /documents/drivers/DRV-009/
A11: Driver 10 | B11: DRV-010 | C11: Noah Wilson | D11: 582-987-2387 | E11: 110 W Adams St, Chicago, IL 60603 | F11: 46647 | G11: 46752 | H11: 46465.5 | I11: T-105 | J11: ✅ COMPLIANT | K11: /drivers/DRV-010.jpg | L11: /documents/drivers/DRV-010_CDL.pdf | M11: /documents/drivers/DRV-010_MVR.pdf | N11: /documents/drivers/DRV-010_MEDICAL.pdf | O11: COMPLIANT | P11: T-105 | Q11: /documents/drivers/DRV-010_W9.pdf | R11: /documents/drivers/DRV-010_I9.pdf | S11: /documents/drivers/DRV-010_FMCSA.pdf | T11: /documents/drivers/DRV-010_BANK_INFO.pdf | U11: /documents/drivers/DRV-010/
A12: Driver 11 | B12: DRV-011 | C12: Olivia Lee | D12: 337-857-3607 | E12: 600 Peachtree St, Atlanta, GA 30308 | F12: 46566 | G12: 46499 | H12: 46465.5 | I12: T-114, T-118 | J12: ✅ COMPLIANT | K12: /drivers/DRV-011.jpg | L12: /documents/drivers/DRV-011_CDL.pdf | M12: /documents/drivers/DRV-011_MVR.pdf | N12: /documents/drivers/DRV-011_MEDICAL.pdf | O12: COMPLIANT | P12: T-114 | Q12: /documents/drivers/DRV-011_W9.pdf | R12: /documents/drivers/DRV-011_I9.pdf | S12: /documents/drivers/DRV-011_FMCSA.pdf | T12: /documents/drivers/DRV-011_BANK_INFO.pdf | U12: /documents/drivers/DRV-011/
A13: Driver 12 | B13: DRV-012 | C13: Robert Johnson | D13: 618-623-9317 | E13: 88 S Main St, Akron, OH 44308 | F13: 46135 | G13: 46042 | H13: 45997 | I13: T-106, T-115 | J13: ❌ MED CARD EXPIRED | MVR EXPIRED | K13: /drivers/DRV-012.jpg | L13: /documents/drivers/DRV-012_CDL.pdf | M13: /documents/drivers/DRV-012_MVR.pdf | N13: /documents/drivers/DRV-012_MEDICAL.pdf | O13: NON_COMPLIANT | P13: T-106 | Q13: /documents/drivers/DRV-012_W9.pdf | R13: /documents/drivers/DRV-012_I9.pdf | S13: /documents/drivers/DRV-012_FMCSA.pdf | T13: /documents/drivers/DRV-012_BANK_INFO.pdf | U13: /documents/drivers/DRV-012/

Sheet Documents_Clean
A1: Driver ID | B1: Full Name | C1: Phone | D1: Address | E1: Compliance Status | F1: Document Type | G1: Expiration Date | H1: File Link | I1: Standard Doc Type | J1: Document URL | K1: Doc Status | L1: Export Key | M1: File Name | N1: Driver Photo URL | O1: Preview Image URL
A2: DRV-001 | B2: John Carter | C2: 206-667-3424 | D2: 1240 W 6th St, Cleveland, OH | E2: NON-COMPLIANT | F2: CDL Summary | G2: 46259 | H2: /documents/drivers/DRV-001_CDL.pdf | I2: CDL | J2: /documents/drivers/DRV-001_CDL.pdf | K2: =IF(G2="","MISSING_DATE",IF(G2<TODAY(),"EXPIRED",IF(G2<=TODAY()+30,"EXPIRING_SOON","VALID"))) | L2: DRV-001|CDL | M2: DRV-001_CDL.pdf | N2: /drivers/DRV-001.jpg | O2: /images/documents/DRV-001_CDL.jpg
A3: DRV-001 | B3: John Carter | C3: 206-667-3424 | D3: 1240 W 6th St, Cleveland, OH | E3: NON-COMPLIANT | F3: Medical Certification Summary | G3: 46029 | H3: /documents/drivers/DRV-001_MEDICAL.pdf | I3: MEDICAL_CARD | J3: /documents/drivers/DRV-001_MEDICAL.pdf | K3: =IF(G3="","MISSING_DATE",IF(G3<TODAY(),"EXPIRED",IF(G3<=TODAY()+30,"EXPIRING_SOON","VALID"))) | L3: DRV-001|MEDICAL_CARD | M3: DRV-001_MEDICAL.pdf | N3: /drivers/DRV-001.jpg | O3: /images/documents/DRV-001_MEDICAL_CARD.jpg
A4: DRV-001 | B4: John Carter | C4: 206-667-3424 | D4: 1240 W 6th St, Cleveland, OH | E4: NON-COMPLIANT | F4: MVR Summary | G4: 46037 | H4: /documents/drivers/DRV-001_MVR.pdf | I4: MVR | J4: /documents/drivers/DRV-001_MVR.pdf | K4: =IF(G4="","MISSING_DATE",IF(G4<TODAY(),"EXPIRED",IF(G4<=TODAY()+30,"EXPIRING_SOON","VALID"))) | L4: DRV-001|MVR | M4: DRV-001_MVR.pdf | N4: /drivers/DRV-001.jpg | O4: /images/documents/DRV-001_MVR.jpg
A5: DRV-001 | B5: John Carter | C5: 206-667-3424 | D5: 1240 W 6th St, Cleveland, OH | E5: NON-COMPLIANT | F5: Employment Eligibility Summary | G5: 46104 | H5: /documents/drivers/DRV-001_I9.pdf | I5: I9 | J5: /documents/drivers/DRV-001_I9.pdf | K5: =IF(G5="","MISSING_DATE",IF(G5<TODAY(),"EXPIRED",IF(G5<=TODAY()+30,"EXPIRING_SOON","VALID"))) | L5: DRV-001|I9 | M5: DRV-001_I9.pdf | N5: /drivers/DRV-001.jpg | O5: /images/documents/DRV-001_I9.jpg
A6: DRV-001 | B6: John Carter | C6: 206-667-3424 | D6: 1240 W 6th St, Cleveland, OH | E6: NON-COMPLIANT | F6: FMCSA Compliance Summary | G6: 45978 | H6: /documents/drivers/DRV-001_FMCSA.pdf | I6: FMCSA | J6: /documents/drivers/DRV-001_FMCSA.pdf | K6: =IF(G6="","MISSING_DATE",IF(G6<TODAY(),"EXPIRED",IF(G6<=TODAY()+30,"EXPIRING_SOON","VALID"))) | L6: DRV-001|FMCSA | M6: DRV-001_FMCSA.pdf | N6: /drivers/DRV-001.jpg | O6: /images/documents/DRV-001_FMCSA.jpg
A7: DRV-001 | B7: John Carter | C7: 206-667-3424 | D7: 1240 W 6th St, Cleveland, OH | E7: NON-COMPLIANT | F7: W-9 Summary | G7: 46190 | H7: /documents/drivers/DRV-001_W9.pdf | I7: W9 | J7: /documents/drivers/DRV-001_W9.pdf | K7: =IF(G7="","MISSING_DATE",IF(G7<TODAY(),"EXPIRED",IF(G7<=TODAY()+30,"EXPIRING_SOON","VALID"))) | L7: DRV-001|W9 | M7: DRV-001_W9.pdf | N7: /drivers/DRV-001.jpg | O7: /images/documents/DRV-001_W9.jpg
A8: DRV-001 | B8: John Carter | C8: 206-667-3424 | D8: 1240 W 6th St, Cleveland, OH | E8: NON-COMPLIANT | F8: Bank Information Sheet | G8: 46074 | H8: /documents/drivers/DRV-001_BANK_INFO.pdf | I8: BANK_INFO | J8: /documents/drivers/DRV-001_BANK_INFO.pdf | K8: =IF(G8="","MISSING_DATE",IF(G8<TODAY(),"EXPIRED",IF(G8<=TODAY()+30,"EXPIRING_SOON","VALID"))) | L8: DRV-001|BANK_INFO | M8: DRV-001_BANK_INFO.pdf | N8: /drivers/DRV-001.jpg | O8: /images/documents/DRV-001_BANK_INFO.jpg
A9: DRV-002 | B9: Maria Lopez | C9: 707-773-6386 | D9: 450 N Michigan Ave, Chicago, IL | E9: NON-COMPLIANT | F9: Medical Certification Summary | G9: 46264 | H9: /documents/drivers/DRV-002_MEDICAL.pdf | I9: MEDICAL_CARD | J9: /documents/drivers/DRV-002_MEDICAL.pdf | K9: =IF(G9="","MISSING_DATE",IF(G9<TODAY(),"EXPIRED",IF(G9<=TODAY()+30,"EXPIRING_SOON","VALID"))) | L9: DRV-002|MEDICAL_CARD | M9: DRV-002_MEDICAL.pdf | N9: /drivers/DRV-002.jpg | O9: /images/documents/DRV-002_MEDICAL_CARD.jpg
A10: DRV-002 | B10: Maria Lopez | C10: 707-773-6386 | D10: 450 N Michigan Ave, Chicago, IL | E10: NON-COMPLIANT | F10: Medical Certification Summary | G10: 46264 | H10: /documents/drivers/DRV-002_MEDICAL.pdf | I10: MEDICAL_CARD | J10: /documents/drivers/DRV-002_MEDICAL.pdf | K10: =IF(G10="","MISSING_DATE",IF(G10<TODAY(),"EXPIRED",IF(G10<=TODAY()+30,"EXPIRING_SOON","VALID"))) | L10: DRV-002|MEDICAL_CARD | M10: DRV-002_MEDICAL.pdf | N10: /drivers/DRV-002.jpg | O10: /images/documents/DRV-002_MEDICAL_CARD.jpg
A11: DRV-002 | B11: Maria Lopez | C11: 707-773-6386 | D11: 450 N Michigan Ave, Chicago, IL | E11: NON-COMPLIANT | F11: MVR Summary | G11: 46037 | H11: /documents/drivers/DRV-002_MVR.pdf | I11: MVR | J11: /documents/drivers/DRV-002_MVR.pdf | K11: =IF(G11="","MISSING_DATE",IF(G11<TODAY(),"EXPIRED",IF(G11<=TODAY()+30,"EXPIRING_SOON","VALID"))) | L11: DRV-002|MVR | M11: DRV-002_MVR.pdf | N11: /drivers/DRV-002.jpg | O11: /images/documents/DRV-002_MVR.jpg
A12: DRV-002 | B12: Maria Lopez | C12: 707-773-6386 | D12: 450 N Michigan Ave, Chicago, IL | E12: NON-COMPLIANT | F12: Employment Eligibility Summary | G12: 46049 | H12: /documents/drivers/DRV-002_I9.pdf | I12: I9 | J12: /documents/drivers/DRV-002_I9.pdf | K12: =IF(G12="","MISSING_DATE",IF(G12<TODAY(),"EXPIRED",IF(G12<=TODAY()+30,"EXPIRING_SOON","VALID"))) | L12: DRV-002|I9 | M12: DRV-002_I9.pdf | N12: /drivers/DRV-002.jpg | O12: /images/documents/DRV-002_I9.jpg
A13: DRV-002 | B13: Maria Lopez | C13: 707-773-6386 | D13: 450 N Michigan Ave, Chicago, IL | E13: NON-COMPLIANT | F13: FMCSA Compliance Summary | G13: 46182 | H13: /documents/drivers/DRV-002_FMCSA.pdf | I13: FMCSA | J13: /documents/drivers/DRV-002_FMCSA.pdf | K13: =IF(G13="","MISSING_DATE",IF(G13<TODAY(),"EXPIRED",IF(G13<=TODAY()+30,"EXPIRING_SOON","VALID"))) | L13: DRV-002|FMCSA | M13: DRV-002_FMCSA.pdf | N13: /drivers/DRV-002.jpg | O13: /images/documents/DRV-002_FMCSA.jpg
... A85: DRV-012 | B85: Robert Johnson | C85: 618-623-9317 | D85: 88 S Main St, Akron, OH | E85: VALID | F85: Bank Information Sheet | G85: 46069 | H85: /documents/drivers/DRV-012_BANK_INFO.pdf | I85: BANK_INFO | J85: /documents/drivers/DRV-012_BANK_INFO.pdf | K85: =IF(G85="","MISSING_DATE",IF(G85<TODAY(),"EXPIRED",IF(G85<=TODAY()+30,"EXPIRING_SOON","VALID"))) | L85: DRV-012|BANK_INFO | M85: DRV-012_BANK_INFO.pdf | N85: /drivers/DRV-012.jpg | O85: /images/documents/DRV-012_BANK_INFO.jpg

Sheet Assets_Clean
A1: Asset ID | B1: Assigned Driver ID | C1: Assigned Driver Name | D1: Last Service Date | E1: Next Service Date | F1: Status Indicator | G1: Service Status | H1: Export Ready
A2: T-101 | B2: DRV-012 | D2: 45777 | E2: 46119 | F2: =IF(E2<TODAY(),"EXPIRED",IF(E2<=TODAY()+30,"DUE_SOON","OK")) | G2: =IF(E2<TODAY(),"EXPIRED",IF(E2<=TODAY()+30,"DUE_SOON","OK")) | H2: YES
A3: T-102 | B3: DRV-001 | C3: John Carter | D3: 46011 | E3: 46067 | F3: =IF(E3<TODAY(),"EXPIRED",IF(E3<=TODAY()+30,"DUE_SOON","OK")) | G3: =IF(E3<TODAY(),"EXPIRED",IF(E3<=TODAY()+30,"DUE_SOON","OK")) | H3: YES
A4: T-103 | B4: DRV-006 | C4: Marcus Chen | D4: 45781 | E4: 46095 | F4: =IF(E4<TODAY(),"EXPIRED",IF(E4<=TODAY()+30,"DUE_SOON","OK")) | G4: =IF(E4<TODAY(),"EXPIRED",IF(E4<=TODAY()+30,"DUE_SOON","OK")) | H4: YES
A5: T-104 | B5: DRV-005 | C5: Kenji Tanaka | D5: 45726 | E5: 46077 | F5: =IF(E5<TODAY(),"EXPIRED",IF(E5<=TODAY()+30,"DUE_SOON","OK")) | G5: =IF(E5<TODAY(),"EXPIRED",IF(E5<=TODAY()+30,"DUE_SOON","OK")) | H5: YES
A6: T-105 | B6: DRV-010 | C6: Noah Wilson | D6: 45747 | E6: 46165 | F6: =IF(E6<TODAY(),"EXPIRED",IF(E6<=TODAY()+30,"DUE_SOON","OK")) | G6: =IF(E6<TODAY(),"EXPIRED",IF(E6<=TODAY()+30,"DUE_SOON","OK")) | H6: YES
A7: T-106 | B7: DRV-008 | C7: Liam Smith | D7: 45662 | E7: 46105 | F7: =IF(E7<TODAY(),"EXPIRED",IF(E7<=TODAY()+30,"DUE_SOON","OK")) | G7: =IF(E7<TODAY(),"EXPIRED",IF(E7<=TODAY()+30,"DUE_SOON","OK")) | H7: YES
A8: T-107 | B8: DRV-003 | C8: Alex Kim | D8: 45821 | E8: 46067 | F8: =IF(E8<TODAY(),"EXPIRED",IF(E8<=TODAY()+30,"DUE_SOON","OK")) | G8: =IF(E8<TODAY(),"EXPIRED",IF(E8<=TODAY()+30,"DUE_SOON","OK")) | H8: YES
A9: T-108 | B9: DRV-004 | C9: Priya Patel | D9: 45764 | E9: 46127 | F9: =IF(E9<TODAY(),"EXPIRED",IF(E9<=TODAY()+30,"DUE_SOON","OK")) | G9: =IF(E9<TODAY(),"EXPIRED",IF(E9<=TODAY()+30,"DUE_SOON","OK")) | H9: YES
A10: T-109 | B10: DRV-009 | C10: Emma Brown | D10: 45879 | E10: 46062 | F10: =IF(E10<TODAY(),"EXPIRED",IF(E10<=TODAY()+30,"DUE_SOON","OK")) | G10: =IF(E10<TODAY(),"EXPIRED",IF(E10<=TODAY()+30,"DUE_SOON","OK")) | H10: YES
A11: T-110 | B11: DRV-004 | C11: Priya Patel | D11: 45997 | E11: 46096 | F11: =IF(E11<TODAY(),"EXPIRED",IF(E11<=TODAY()+30,"DUE_SOON","OK")) | G11: =IF(E11<TODAY(),"EXPIRED",IF(E11<=TODAY()+30,"DUE_SOON","OK")) | H11: YES
A12: T-111 | B12: DRV-007 | C12: Sofia Gomez | D12: 46012 | E12: 46158 | F12: =IF(E12<TODAY(),"EXPIRED",IF(E12<=TODAY()+30,"DUE_SOON","OK")) | G12: =IF(E12<TODAY(),"EXPIRED",IF(E12<=TODAY()+30,"DUE_SOON","OK")) | H12: YES
A13: T-112 | B13: DRV-005 | C13: Kenji Tanaka | D13: 46021 | E13: 46171 | F13: =IF(E13<TODAY(),"EXPIRED",IF(E13<=TODAY()+30,"DUE_SOON","OK")) | G13: =IF(E13<TODAY(),"EXPIRED",IF(E13<=TODAY()+30,"DUE_SOON","OK")) | H13: YES
A14: T-113 | B14: DRV-004 | C14: Priya Patel | D14: 45907 | E14: 46090 | F14: =IF(E14<TODAY(),"EXPIRED",IF(E14<=TODAY()+30,"DUE_SOON","OK")) | G14: =IF(E14<TODAY(),"EXPIRED",IF(E14<=TODAY()+30,"DUE_SOON","OK")) | H14: YES
A15: T-114 | B15: DRV-011 | C15: Olivia Lee | D15: 45916 | E15: 46171 | F15: =IF(E15<TODAY(),"EXPIRED",IF(E15<=TODAY()+30,"DUE_SOON","OK")) | G15: =IF(E15<TODAY(),"EXPIRED",IF(E15<=TODAY()+30,"DUE_SOON","OK")) | H15: YES
A16: T-115 | B16: DRV-012 | D16: 45848 | E16: 46100 | F16: =IF(E16<TODAY(),"EXPIRED",IF(E16<=TODAY()+30,"DUE_SOON","OK")) | G16: =IF(E16<TODAY(),"EXPIRED",IF(E16<=TODAY()+30,"DUE_SOON","OK")) | H16: YES
A17: T-116 | B17: DRV-004 | C17: Priya Patel | D17: 45681 | E17: 46166 | F17: =IF(E17<TODAY(),"EXPIRED",IF(E17<=TODAY()+30,"DUE_SOON","OK")) | G17: =IF(E17<TODAY(),"EXPIRED",IF(E17<=TODAY()+30,"DUE_SOON","OK")) | H17: YES
A18: T-117 | B18: DRV-006 | C18: Marcus Chen | D18: 45785 | E18: 46069 | F18: =IF(E18<TODAY(),"EXPIRED",IF(E18<=TODAY()+30,"DUE_SOON","OK")) | G18: =IF(E18<TODAY(),"EXPIRED",IF(E18<=TODAY()+30,"DUE_SOON","OK")) | H18: YES
A19: T-118 | B19: DRV-011 | C19: Olivia Lee | D19: 45916 | E19: 46134 | F19: =IF(E19<TODAY(),"EXPIRED",IF(E19<=TODAY()+30,"DUE_SOON","OK")) | G19: =IF(E19<TODAY(),"EXPIRED",IF(E19<=TODAY()+30,"DUE_SOON","OK")) | H19: YES
A20: T-119 | B20: DRV-006 | C20: Marcus Chen | D20: 45959 | E20: 46129 | F20: =IF(E20<TODAY(),"EXPIRED",IF(E20<=TODAY()+30,"DUE_SOON","OK")) | G20: =IF(E20<TODAY(),"EXPIRED",IF(E20<=TODAY()+30,"DUE_SOON","OK")) | H20: YES
A21: T-120 | B21: DRV-008 | C21: Liam Smith | D21: 45986 | E21: 46098 | F21: =IF(E21<TODAY(),"EXPIRED",IF(E21<=TODAY()+30,"DUE_SOON","OK")) | G21: =IF(E21<TODAY(),"EXPIRED",IF(E21<=TODAY()+30,"DUE_SOON","OK")) | H21: YES
A22: T-121 | B22: DRV-001 | C22: John Carter | D22: 45743 | E22: 46064 | F22: =IF(E22<TODAY(),"EXPIRED",IF(E22<=TODAY()+30,"DUE_SOON","OK")) | G22: =IF(E22<TODAY(),"EXPIRED",IF(E22<=TODAY()+30,"DUE_SOON","OK")) | H22: YES
A23: T-122 | B23: DRV-002 | C23: Maria Lopez | D23: 45843 | E23: 46106 | F23: =IF(E23<TODAY(),"EXPIRED",IF(E23<=TODAY()+30,"DUE_SOON","OK")) | G23: =IF(E23<TODAY(),"EXPIRED",IF(E23<=TODAY()+30,"DUE_SOON","OK")) | H23: YES
A24: T-123 | B24: DRV-003 | C24: Alex Kim | D24: 45951 | E24: 46100 | F24: =IF(E24<TODAY(),"EXPIRED",IF(E24<=TODAY()+30,"DUE_SOON","OK")) | G24: =IF(E24<TODAY(),"EXPIRED",IF(E24<=TODAY()+30,"DUE_SOON","OK")) | H24: YES
A25: T-124 | B25: DRV-002 | C25: Maria Lopez | D25: 45873 | E25: 46102 | F25: =IF(E25<TODAY(),"EXPIRED",IF(E25<=TODAY()+30,"DUE_SOON","OK")) | G25: =IF(E25<TODAY(),"EXPIRED",IF(E25<=TODAY()+30,"DUE_SOON","OK")) | H25: YES
A26: T-125 | B26: DRV-002 | C26: Maria Lopez | D26: 45773 | E26: 46084 | F26: =IF(E26<TODAY(),"EXPIRED",IF(E26<=TODAY()+30,"DUE_SOON","OK")) | G26: =IF(E26<TODAY(),"EXPIRED",IF(E26<=TODAY()+30,"DUE_SOON","OK")) | H26: YES

Sheet Dispatch_Clean
A1: Load ID | B1: Driver ID | C1: Driver Name | D1: Asset ID | E1: Revenue | F1: Backhaul Pay | G1: Driver Signature? | H1: Load Status | I1: Reason for Pending Status | J1: Seal Number (Pickup) | K1: Seal Photo (Pickup) | L1: Seal Number (Delivery) | M1: Seal Photo (Delivery) | N1: Seal Status | O1: Exception Flag | P1: Override Reason | Q1: Audit Log | R1: Compliance Lock | S1: Seal Issue Type | T1: Photo Required? | U1: Review Status | V1: Legacy Driver ID | W1: Revenue Status | X1: Export Load Status | Y1: Rate Confirmation URL | Z1: BOL URL | AA1: Pickup Seal Photo URL | AB1: Delivery Seal Photo URL | AC1: Driver Photo URL | AD1: POD Image URL | AE1: Pickup Image URL | AF1: Delivery Image URL | AG1: Lumper Image URL
A2: L-501 | B2: DRV-001 | C2: John Carter | D2: T-102 | E2: 2000 | F2: 65 | G2: NO | H2: DELIVERED | J2: SEAL-83921 | K2: pickup_photo_01.jpg | L2: SEAL-83920 | M2: delivery_photo_01.jpg | N2: =IF(L2="","PENDING",IF(L2<>J2,"MISMATCH","VERIFIED")) | O2: =IF(N2="MISMATCH","SEAL_MISMATCH",IF(OR(K2="",M2=""),"PHOTO_MISSING","")) | Q2: =IF(O2="","",CONCAT("Pickup:",J2," | Delivery:",L2," | Override:",IF(P2="","NONE",P2))) | R2: =IF(O2="","CLEAR",IF(P2="","LOCKED","OVERRIDDEN")) | S2: SEAL_MISMATCH | T2: YES | U2: OPEN | V2: Driver 1 | W2: READY | X2: DELIVERED | Y2: /documents/loads/L-501_RC.pdf | Z2: /documents/loads/L-501_BOL.pdf | AA2: /documents/loads/L-501_PICKUP_SEAL.jpg | AB2: /documents/loads/L-501_DELIVERY_SEAL.jpg | AC2: /drivers/DRV-001.jpg | AD2: /images/pod/L-501_POD.jpg | AE2: /images/pickup/L-501_PICKUP.jpg | AF2: /images/delivery/L-501_DELIVERY.jpg | AG2: /images/lumper/L-501_LUMPER.jpg
A3: L-502 | B3: DRV-002 | C3: Maria Lopez | D3: T-101 | E3: 1800 | F3: 95 | G3: NO | H3: IN_TRANSIT | J3: SEAL-55219 | K3: pickup_photo_02.jpg | L3: SEAL-55219 | M3: delivery_photo_02.jpg | N3: =IF(L3="","PENDING",IF(L3<>J3,"MISMATCH","VERIFIED")) | O3: =IF(N3="MISMATCH","SEAL_MISMATCH",IF(OR(K3="",M3=""),"PHOTO_MISSING","")) | Q3: =IF(O3="","",CONCAT("Pickup:",J3," | Delivery:",L3," | Override:",IF(P3="","NONE",P3))) | R3: =IF(O3="","CLEAR",IF(P3="","LOCKED","OVERRIDDEN")) | S3: VERIFIED | T3: NO | U3: CLOSED | V3: Driver 2 | W3: PENDING | X3: IN_TRANSIT | Y3: /documents/loads/L-502_RC.pdf | Z3: /documents/loads/L-502_BOL.pdf | AA3: /documents/loads/L-502_PICKUP_SEAL.jpg | AB3: /documents/loads/L-502_DELIVERY_SEAL.jpg | AC3: /drivers/DRV-002.jpg | AD3: /images/pod/L-502_POD.jpg | AE3: /images/pickup/L-502_PICKUP.jpg | AF3: /images/delivery/L-502_DELIVERY.jpg | AG3: /images/lumper/L-502_LUMPER.jpg
A4: L-503 | B4: DRV-003 | C4: Alex Kim | D4: T-107 | E4: 2100 | F4: 45 | G4: NO | H4: DELIVERED | J4: SEAL-77102 | K4: pickup_photo_03.jpg | N4: =IF(L4="","PENDING",IF(L4<>J4,"MISMATCH","VERIFIED")) | O4: =IF(N4="MISMATCH","SEAL_MISMATCH",IF(OR(K4="",M4=""),"PHOTO_MISSING","")) | Q4: =IF(O4="","",CONCAT("Pickup:",J4," | Delivery:",L4," | Override:",IF(P4="","NONE",P4))) | R4: =IF(O4="","CLEAR",IF(P4="","LOCKED","OVERRIDDEN")) | S4: MISSING_DELIVERY_SEAL | T4: YES | U4: OPEN | V4: Driver 3 | W4: READY | X4: DELIVERED | Y4: /documents/loads/L-503_RC.pdf | Z4: /documents/loads/L-503_BOL.pdf | AA4: /documents/loads/L-503_PICKUP_SEAL.jpg | AB4: /documents/loads/L-503_DELIVERY_SEAL.jpg | AC4: /drivers/DRV-003.jpg | AD4: /images/pod/L-503_POD.jpg | AE4: /images/pickup/L-503_PICKUP.jpg | AF4: /images/delivery/L-503_DELIVERY.jpg | AG4: /images/lumper/L-503_LUMPER.jpg
A5: L-504 | B5: DRV-004 | C5: Priya Patel | D5: T-108 | E5: 1950 | F5: 88 | G5: YES | H5: PENDING | I5: Awaiting POD | J5: SEAL-61044 | K5: pickup_photo_04.jpg | L5: SEAL-61043 | M5: delivery_photo_04.jpg | N5: =IF(L5="","PENDING",IF(L5<>J5,"MISMATCH","VERIFIED")) | O5: =IF(N5="MISMATCH","SEAL_MISMATCH",IF(OR(K5="",M5=""),"PHOTO_MISSING","")) | P5: Dock supervisor approved | Q5: =IF(O5="","",CONCAT("Pickup:",J5," | Delivery:",L5," | Override:",IF(P5="","NONE",P5))) | R5: =IF(O5="","CLEAR",IF(P5="","LOCKED","OVERRIDDEN")) | S5: SEAL_MISMATCH | T5: YES | U5: OPEN | V5: Driver 4 | W5: PENDING | X5: PENDING | Y5: /documents/loads/L-504_RC.pdf | Z5: /documents/loads/L-504_BOL.pdf | AA5: /documents/loads/L-504_PICKUP_SEAL.jpg | AB5: /documents/loads/L-504_DELIVERY_SEAL.jpg | AC5: /drivers/DRV-004.jpg | AD5: /images/pod/L-504_POD.jpg | AE5: /images/pickup/L-504_PICKUP.jpg | AF5: /images/delivery/L-504_DELIVERY.jpg | AG5: /images/lumper/L-504_LUMPER.jpg
A6: L-505 | B6: DRV-005 | C6: Kenji Tanaka | D6: T-104 | E6: 2200 | F6: 45 | G6: NO | H6: DELIVERED | J6: SEAL-44018 | K6: pickup_photo_05.jpg | L6: SEAL-44018 | M6: delivery_photo_05.jpg | N6: =IF(L6="","PENDING",IF(L6<>J6,"MISMATCH","VERIFIED")) | O6: =IF(N6="MISMATCH","SEAL_MISMATCH",IF(OR(K6="",M6=""),"PHOTO_MISSING","")) | Q6: =IF(O6="","",CONCAT("Pickup:",J6," | Delivery:",L6," | Override:",IF(P6="","NONE",P6))) | R6: =IF(O6="","CLEAR",IF(P6="","LOCKED","OVERRIDDEN")) | S6: VERIFIED | T6: NO | U6: CLOSED | V6: Driver 5 | W6: READY | X6: DELIVERED | Y6: /documents/loads/L-505_RC.pdf | Z6: /documents/loads/L-505_BOL.pdf | AA6: /documents/loads/L-505_PICKUP_SEAL.jpg | AB6: /documents/loads/L-505_DELIVERY_SEAL.jpg | AC6: /drivers/DRV-005.jpg | AD6: /images/pod/L-505_POD.jpg | AE6: /images/pickup/L-505_PICKUP.jpg | AF6: /images/delivery/L-505_DELIVERY.jpg | AG6: /images/lumper/L-505_LUMPER.jpg
A7: L-506 | B7: DRV-006 | C7: Marcus Chen | D7: T-103 | E7: 2050 | F7: 72 | G7: YES | H7: DELIVERED | J7: SEAL-99871 | K7: pickup_photo_06.jpg | N7: =IF(L7="","PENDING",IF(L7<>J7,"MISMATCH","VERIFIED")) | O7: =IF(N7="MISMATCH","SEAL_MISMATCH",IF(OR(K7="",M7=""),"PHOTO_MISSING","")) | Q7: =IF(O7="","",CONCAT("Pickup:",J7," | Delivery:",L7," | Override:",IF(P7="","NONE",P7))) | R7: =IF(O7="","CLEAR",IF(P7="","LOCKED","OVERRIDDEN")) | S7: MISSING_DELIVERY_SEAL | T7: YES | U7: OPEN | V7: Driver 6 | W7: READY | X7: DELIVERED | Y7: /documents/loads/L-506_RC.pdf | Z7: /documents/loads/L-506_BOL.pdf | AA7: /documents/loads/L-506_PICKUP_SEAL.jpg | AB7: /documents/loads/L-506_DELIVERY_SEAL.jpg | AC7: /drivers/DRV-006.jpg | AD7: /images/pod/L-506_POD.jpg | AE7: /images/pickup/L-506_PICKUP.jpg | AF7: /images/delivery/L-506_DELIVERY.jpg | AG7: /images/lumper/L-506_LUMPER.jpg
A8: L-507 | B8: DRV-007 | C8: Sofia Gomez | D8: T-109 | E8: 2300 | F8: 58 | G8: NO | H8: IN_TRANSIT | J8: SEAL-73005 | K8: pickup_photo_07.jpg | L8: SEAL-73099 | M8: delivery_photo_07.jpg | N8: =IF(L8="","PENDING",IF(L8<>J8,"MISMATCH","VERIFIED")) | O8: =IF(N8="MISMATCH","SEAL_MISMATCH",IF(OR(K8="",M8=""),"PHOTO_MISSING","")) | Q8: =IF(O8="","",CONCAT("Pickup:",J8," | Delivery:",L8," | Override:",IF(P8="","NONE",P8))) | R8: =IF(O8="","CLEAR",IF(P8="","LOCKED","OVERRIDDEN")) | S8: SEAL_MISMATCH | T8: YES | U8: OPEN | V8: Driver 7 | W8: PENDING | X8: IN_TRANSIT | Y8: /documents/loads/L-507_RC.pdf | Z8: /documents/loads/L-507_BOL.pdf | AA8: /documents/loads/L-507_PICKUP_SEAL.jpg | AB8: /documents/loads/L-507_DELIVERY_SEAL.jpg | AC8: /drivers/DRV-007.jpg | AD8: /images/pod/L-507_POD.jpg | AE8: /images/pickup/L-507_PICKUP.jpg | AF8: /images/delivery/L-507_DELIVERY.jpg | AG8: /images/lumper/L-507_LUMPER.jpg
A9: L-508 | B9: DRV-008 | C9: Liam Smith | D9: T-110 | E9: 1750 | F9: 81 | G9: YES | H9: DELIVERED | J9: SEAL-18542 | K9: pickup_photo_08.jpg | L9: SEAL-18542 | M9: delivery_photo_08.jpg | N9: =IF(L9="","PENDING",IF(L9<>J9,"MISMATCH","VERIFIED")) | O9: =IF(N9="MISMATCH","SEAL_MISMATCH",IF(OR(K9="",M9=""),"PHOTO_MISSING","")) | Q9: =IF(O9="","",CONCAT("Pickup:",J9," | Delivery:",L9," | Override:",IF(P9="","NONE",P9))) | R9: =IF(O9="","CLEAR",IF(P9="","LOCKED","OVERRIDDEN")) | S9: VERIFIED | T9: NO | U9: CLOSED | V9: Driver 8 | W9: READY | X9: DELIVERED | Y9: /documents/loads/L-508_RC.pdf | Z9: /documents/loads/L-508_BOL.pdf | AA9: /documents/loads/L-508_PICKUP_SEAL.jpg | AB9: /documents/loads/L-508_DELIVERY_SEAL.jpg | AC9: /drivers/DRV-008.jpg | AD9: /images/pod/L-508_POD.jpg | AE9: /images/pickup/L-508_PICKUP.jpg | AF9: /images/delivery/L-508_DELIVERY.jpg | AG9: /images/lumper/L-508_LUMPER.jpg
A10: L-509 | B10: DRV-009 | C10: Emma Brown | D10: T-111 | E10: 2400 | F10: 49 | G10: NO | H10: PENDING | I10: Customer hold | J10: SEAL-26790 | K10: pickup_photo_09.jpg | L10: SEAL-26791 | M10: delivery_photo_09.jpg | N10: =IF(L10="","PENDING",IF(L10<>J10,"MISMATCH","VERIFIED")) | O10: =IF(N10="MISMATCH","SEAL_MISMATCH",IF(OR(K10="",M10=""),"PHOTO_MISSING","")) | P10: Carrier note logged | Q10: =IF(O10="","",CONCAT("Pickup:",J10," | Delivery:",L10," | Override:",IF(P10="","NONE",P10))) | R10: =IF(O10="","CLEAR",IF(P10="","LOCKED","OVERRIDDEN")) | S10: SEAL_MISMATCH | T10: YES | U10: OPEN | V10: Driver 9 | W10: PENDING | X10: PENDING | Y10: /documents/loads/L-509_RC.pdf | Z10: /documents/loads/L-509_BOL.pdf | AA10: /documents/loads/L-509_PICKUP_SEAL.jpg | AB10: /documents/loads/L-509_DELIVERY_SEAL.jpg | AC10: /drivers/DRV-009.jpg | AD10: /images/pod/L-509_POD.jpg | AE10: /images/pickup/L-509_PICKUP.jpg | AF10: /images/delivery/L-509_DELIVERY.jpg | AG10: /images/lumper/L-509_LUMPER.jpg
A11: L-510 | B11: DRV-010 | C11: Noah Wilson | D11: T-105 | E11: 1900 | F11: 77 | G11: YES | H11: DELIVERED | J11: SEAL-48113 | K11: pickup_photo_10.jpg | N11: =IF(L11="","PENDING",IF(L11<>J11,"MISMATCH","VERIFIED")) | O11: =IF(N11="MISMATCH","SEAL_MISMATCH",IF(OR(K11="",M11=""),"PHOTO_MISSING","")) | Q11: =IF(O11="","",CONCAT("Pickup:",J11," | Delivery:",L11," | Override:",IF(P11="","NONE",P11))) | R11: =IF(O11="","CLEAR",IF(P11="","LOCKED","OVERRIDDEN")) | S11: MISSING_DELIVERY_SEAL | T11: YES | U11: OPEN | V11: Driver 10 | W11: READY | X11: DELIVERED | Y11: /documents/loads/L-510_RC.pdf | Z11: /documents/loads/L-510_BOL.pdf | AA11: /documents/loads/L-510_PICKUP_SEAL.jpg | AB11: /documents/loads/L-510_DELIVERY_SEAL.jpg | AC11: /drivers/DRV-010.jpg | AD11: /images/pod/L-510_POD.jpg | AE11: /images/pickup/L-510_PICKUP.jpg | AF11: /images/delivery/L-510_DELIVERY.jpg | AG11: /images/lumper/L-510_LUMPER.jpg
A12: L-511 | B12: DRV-011 | C12: Olivia Lee | D12: T-112 | E12: 2250 | F12: 63 | G12: NO | H12: IN_TRANSIT | J12: SEAL-91420 | K12: pickup_photo_11.jpg | L12: SEAL-91420 | M12: delivery_photo_11.jpg | N12: =IF(L12="","PENDING",IF(L12<>J12,"MISMATCH","VERIFIED")) | O12: =IF(N12="MISMATCH","SEAL_MISMATCH",IF(OR(K12="",M12=""),"PHOTO_MISSING","")) | Q12: =IF(O12="","",CONCAT("Pickup:",J12," | Delivery:",L12," | Override:",IF(P12="","NONE",P12))) | R12: =IF(O12="","CLEAR",IF(P12="","LOCKED","OVERRIDDEN")) | S12: VERIFIED | T12: NO | U12: CLOSED | V12: Driver 11 | W12: PENDING | X12: IN_TRANSIT | Y12: /documents/loads/L-511_RC.pdf | Z12: /documents/loads/L-511_BOL.pdf | AA12: /documents/loads/L-511_PICKUP_SEAL.jpg | AB12: /documents/loads/L-511_DELIVERY_SEAL.jpg | AC12: /drivers/DRV-011.jpg | AD12: /images/pod/L-511_POD.jpg | AE12: /images/pickup/L-511_PICKUP.jpg | AF12: /images/delivery/L-511_DELIVERY.jpg | AG12: /images/lumper/L-511_LUMPER.jpg
A13: L-512 | B13: DRV-012 | D13: T-106 | E13: 2150 | F13: 69 | G13: YES | H13: DELIVERED | J13: SEAL-35864 | K13: pickup_photo_12.jpg | L13: SEAL-35860 | M13: delivery_photo_12.jpg | N13: =IF(L13="","PENDING",IF(L13<>J13,"MISMATCH","VERIFIED")) | O13: =IF(N13="MISMATCH","SEAL_MISMATCH",IF(OR(K13="",M13=""),"PHOTO_MISSING","")) | Q13: =IF(O13="","",CONCAT("Pickup:",J13," | Delivery:",L13," | Override:",IF(P13="","NONE",P13))) | R13: =IF(O13="","CLEAR",IF(P13="","LOCKED","OVERRIDDEN")) | S13: SEAL_MISMATCH | T13: YES | U13: OPEN | V13: Driver 12 | W13: READY | X13: DELIVERED | Y13: /documents/loads/L-512_RC.pdf | Z13: /documents/loads/L-512_BOL.pdf | AA13: /documents/loads/L-512_PICKUP_SEAL.jpg | AB13: /documents/loads/L-512_DELIVERY_SEAL.jpg | AC13: /drivers/DRV-012.jpg | AD13: /images/pod/L-512_POD.jpg | AE13: /images/pickup/L-512_PICKUP.jpg | AF13: /images/delivery/L-512_DELIVERY.jpg | AG13: /images/lumper/L-512_LUMPER.jpg

Sheet Payroll_Clean
A1: Driver ID | B1: Full Name | C1: Driver | D1: Base Earnings | E1: Backhaul Pay | F1: Gross Pay | G1: FICA | H1: OASDI | I1: Federal Withholding | J1: State Withholding | K1: SDI | L1: FM Leave | M1: Family Support | N1: Insurance Premiums | O1: Credit Union Savings Club | P1: 401(k) Contribution | Q1: HSA/FSA Health Deduction | R1: Health Insurance Premiums | S1: Life Insurance Above 50k | T1: Total Deductions | U1: Fuel Reimb. | V1: Net Pay | W1: Status | X1: Pending Reason | Y1: 401(k) Rate | Z1: Legacy Driver ID | AA1: Settlement ID | AB1: Export Status | AC1: Settlement URL | AD1: Driver Photo URL
A2: DRV-001 | B2: John Carter | C2: J. Carter | D2: 2100 | E2: 65 | F2: =D2+E2 | G2: =0.062*D2 | H2: =0.0145*D2 | I2: =0.18*D2 | J2: =0.035*D2 | K2: =0.0045*D2 | L2: =0.0066*D2 | M2: 0 | N2: 214.92 | O2: 0 | P2: =D2*Y2 | Q2: 114.79 | R2: 0 | S2: 0 | T2: =SUM(G2:S2) | U2: 0 | V2: =F2-T2+U2 | W2: PAID | Y2: 0.03 | Z2: Driver 1 | AA2: STL-001 | AB2: READY | AC2: /documents/settlements/DRV-001_SETTLEMENT.pdf | AD2: /drivers/DRV-001.jpg
A3: DRV-002 | B3: Maria Lopez | C3: M. Lopez | D3: 1910 | E3: 95 | F3: =D3+E3 | G3: =0.062*D3 | H3: =0.0145*D3 | I3: =0.18*D3 | J3: =0.035*D3 | K3: =0.0045*D3 | L3: =0.0066*D3 | M3: 79.68 | N3: 0 | O3: 42.09 | P3: =D3*Y3 | Q3: 69.33 | R3: 0 | S3: 0 | T3: =SUM(G3:S3) | U3: 120 | V3: =F3-T3+U3 | W3: PENDING | X3: Awaiting Receipts | Y3: 0 | Z3: Driver 2 | AA3: STL-002 | AB3: READY | AC3: /documents/settlements/DRV-002_SETTLEMENT.pdf | AD3: /drivers/DRV-002.jpg
A4: DRV-003 | B4: Alex Kim | C4: A. Kim | D4: 2155 | E4: 45 | F4: =D4+E4 | G4: =0.062*D4 | H4: =0.0145*D4 | I4: =0.18*D4 | J4: =0.035*D4 | K4: =0.0045*D4 | L4: =0.0066*D4 | M4: 0 | N4: 0 | O4: 30.98 | P4: =D4*Y4 | Q4: 0 | R4: 0 | S4: 0 | T4: =SUM(G4:S4) | U4: 0 | V4: =F4-T4+U4 | W4: PAID | Y4: 0.06 | Z4: Driver 3 | AA4: STL-003 | AB4: READY | AC4: /documents/settlements/DRV-003_SETTLEMENT.pdf | AD4: /drivers/DRV-003.jpg
