Workbook

Sheet Driver Data
A1: Driver ID | B1: Full Name | C1: Full Address | D1: Phone | E1: SSN (Masked) | F1: Bank Name | G1: Routing Number | H1: Account Number | I1: Document Type | J1: Status | K1: Document Number | L1: CDL Expiration | M1: Med Card Expiration | N1: MVR Expiration | O1: Incident Details | P1: Hair Color | Q1: Eye Color | R1: Height | S1: Weight | T1: Gender | U1: DOB | V1: Driver Photo | W1: Ethnicity | X1: Email | Y1: Street Address | Z1: City | AA1: State | AB1: ZIP | AC1: State of Residence | AD1: License Class | AE1: CDL Issue Date | AF1: CDL Endorsements | AG1: CDL Restrictions | AH1: Medical Issue Date | AI1: Medical Certificate Number | AJ1: Medical Examiner Name | AK1: Medical Examiner Registry Number | AL1: Medical Restrictions | AM1: Medical Status | AN1: MVR Review Date | AO1: Violation Points | AP1: Accidents on Record | AQ1: MVR Restrictions | AR1: MVR Status | AS1: Hire Date | AT1: Work Authorization Status | AU1: I9 Document 1 | AV1: I9 Document 2 | AW1: I9 Document 3 | AX1: I9 Completion Date | AY1: Employer Representative | AZ1: I9 Status | BA1: Business Name | BB1: Tax Classification | BC1: TIN Type | BD1: TIN | BE1: Exemption Codes | BF1: W9 Submission Date | BG1: W9 Status | BH1: Account Type | BI1: Payment Preference | BJ1: Bank Info Submission Date | BK1: Bank Info Status | BL1: Road Test Date | BM1: Examiner Name | BN1: Vehicle Type | BO1: Trailer Type | BP1: Road Test Location | BQ1: Pre-Trip Inspection Score | BR1: Vehicle Control Score | BS1: Backing Score | BT1: Turning Score | BU1: Braking Score | BV1: Mirror Use Score | BW1: Coupling Score | BX1: Defensive Driving Score | BY1: Overall Safety Score | BZ1: Road Test Result | CA1: Restrictions or Recommendations | CB1: Road Test Status | CC1: Drug and Alcohol Status | CD1: Clearinghouse Status | CE1: Compliance Review Date | CF1: Next Review Date | CG1: Open Deficiencies | CH1: Compliance Status | CI1: Notes | CJ1: First Name | CK1: Last Name | CL1: 5876 Driver License Number | CM1: 5876 License Issuing State | CN1: 5876 CLP/CDL Applicant/Holder | CO1: 5876 Driver Signature Name | CP1: 5876 Driver Signature Date | CQ1: 5876 Certificate Expiration Date | CR1: 5876 Medical Examiner Telephone | CS1: 5876 Medical Examiner Signature Name | CT1: 5876 Date Certificate Signed | CU1: 5876 Medical Examiner License Number | CV1: 5876 National Registry Number | CW1: 5876 Practitioner Type | CX1: 5876 Issuing State/Province | CY1: 5876 Certification Basis | CZ1: 5876 State Variance Details | DA1: 5876 Waiver/Exemption | DB1: 5876 SPE Certificate | DC1: 5876 Exempt Intracity Zone | DD1: 5876 Grandfathered from State Requirements | DE1: 5876 Wearing Corrective Lenses | DF1: 5876 Wearing Hearing Aid | DG1: Emergency Contact Name | DH1: Emergency Contact Relation | DI1: Emergency Contact Phone | DJ1: 5875 High Blood Pressure | DK1: 5875 Diabetes | DL1: 5875 Sleep Apnea | DM1: 5875 Heart Disease | DN1: 5875 Surgeries | DO1: 5875 Vision Score Right | DP1: 5875 Vision Score Left | DQ1: 5875 Hearing Score | DR1: 5875 Blood Pressure Sys | DS1: 5875 Blood Pressure Dia | DT1: 5875 Pulse | DU1: 5875 Urinalysis | DV1: Clearinghouse Consent Date | DW1: Drug Test Result Date | DX1: Drug Test Result | DY1: Safety Policy Ack Date | DZ1: Safety Policy Name | EA1: DQF Status | EB1: DQF Audit Date
A2: DRV-001 | B2: John Carter | C2: 220 Demo Street, Cleveland, OH 44113 | D2: 206-555-0102 | E2: ***-**-0123 | F2: Huntington | G2: 104 | H2: 999900202 | I2: CDL Summary | J2: VALID | K2: OH0000075 | L2: 46621 | M2: 46272 | N2: 46310 | P2: Black | Q2: Green | R2: 5'-10" | S2: 180 | T2: M | U2: 25934 | V2: DRV-001.png | W2: Caucasian | X2: jcarter@example.com | Y2: 220 Demo Street | Z2: Cleveland | AA2: OH | AB2: 44113 | AC2: OH | AD2: Class A | AE2: 44799 | AF2: N,T | AH2: 45364 | AI2: MC-0010108 | AJ2: Dr. Patricia Owens | AK2: ME100001 | AM2: Qualified | AN2: 46050 | AO2: 0 | AP2: 0 | AR2: Clear | AS2: 45392 | AT2: Authorized to Work | AU2: U.S. Passport | AX2: 45392 | AY2: BOF Onboarding Team | AZ2: Complete | BB2: Individual/Sole Proprietor | BC2: SSN | BD2: ***-**-0123 | BF2: 45392 | BG2: Received | BH2: Checking | BI2: Direct Deposit | BJ2: 45392 | BK2: Verified | BL2: 45385 | BM2: A. Reynolds | BN2: Sleeper tractor | BO2: 53 ft dry van | BP2: Cleveland, OH | BQ2: 5 | BR2: 5 | BS2: 4 | BT2: 5 | BU2: 5 | BV2: 5 | BW2: 4 | BX2: 5 | BY2: 5 | BZ2: Pass | CB2: Passed | CC2: Enrolled | CD2: Query Completed | CE2: 46037 | CF2: 46218 | CH2: Compliant | CJ2: John | CK2: Carter | CL2: OH0000075 | CM2: OH | CN2: CDL Holder | CO2: John Carter | CP2: 45364 | CQ2: 46094 | CR2: (614) 555-0107 | CS2: Dr. Patricia Owens | CT2: 45364 | CU2: OH-ME-970443 | CV2: ME100001 | CW2: Chiropractor | CX2: OH | CY2: Federal Motor Carrier Safety Regulations | DA2: No | DB2: No | DC2: No | DD2: No | DE2: No | DF2: No | DG2: Sarah Carter | DH2: Spouse | DI2: 206-555-0199 | DJ2: No | DK2: No | DL2: No | DM2: No | DN2: Yes - Appendectomy (2005) | DO2: 20/20 | DP2: 20/20 | DQ2: Pass | DR2: 118 | DS2: 78 | DT2: 72 | DU2: Normal | DV2: 45392 | DW2: 45394 | DX2: Negative | DY2: 45397 | DZ2: BOF Fleet Safety & Compliance Policy 2024 | EA2: Complete | EB2: 45413
A3: DRV-001 | B3: John Carter | C3: 220 Demo Street, Cleveland, OH 44113 | D3: 206-555-0102 | E3: ***-**-0123 | F3: Huntington | G3: 104 | H3: 999900202 | I3: Medical Certification | J3: VALID | K3: OH0000092 | L3: 46621 | M3: 46273 | N3: 46311 | P3: Black | Q3: Green | R3: 5'-10" | S3: 180 | T3: M | U3: 25934 | V3: DRV-001.png | W3: Caucasian | X3: jcarter@example.com | Y3: 220 Demo Street | Z3: Cleveland | AA3: OH | AB3: 44113 | AC3: OH | AD3: Class A | AE3: 44799 | AF3: N,T | AH3: 45364 | AI3: MC-0010108 | AJ3: Dr. Patricia Owens | AK3: ME100001 | AM3: Qualified | AN3: 46050 | AO3: 0 | AP3: 0 | AR3: Clear | AS3: 45392 | AT3: Authorized to Work | AU3: U.S. Passport | AX3: 45392 | AY3: BOF Onboarding Team | AZ3: Complete | BB3: Individual/Sole Proprietor | BC3: SSN | BD3: ***-**-0123 | BF3: 45392 | BG3: Received | BH3: Checking | BI3: Direct Deposit | BJ3: 45392 | BK3: Verified | BL3: 45385 | BM3: A. Reynolds | BN3: Sleeper tractor | BO3: 53 ft dry van | BP3: Cleveland, OH | BQ3: 5 | BR3: 5 | BS3: 4 | BT3: 5 | BU3: 5 | BV3: 5 | BW3: 4 | BX3: 5 | BY3: 5 | BZ3: Pass | CB3: Passed | CC3: Enrolled | CD3: Query Completed | CE3: 46037 | CF3: 46218 | CH3: Compliant | CJ3: John | CK3: Carter | CL3: OH0000076 | CM3: OH | CN3: CDL Holder | CO3: John Carter | CP3: 45364 | CQ3: 46094 | CR3: (614) 555-0107 | CS3: Dr. Patricia Owens | CT3: 45364 | CU3: OH-ME-970443 | CV3: ME100001 | CW3: Chiropractor | CX3: OH | CY3: Federal Motor Carrier Safety Regulations | DA3: No | DB3: No | DC3: No | DD3: No | DE3: No | DF3: No | DG3: Sarah Carter | DH3: Spouse | DI3: 206-555-0199 | DJ3: No | DK3: No | DL3: No | DM3: No | DN3: Yes - Appendectomy (2005) | DO3: 20/20 | DP3: 20/20 | DQ3: Pass | DR3: 118 | DS3: 78 | DT3: 72 | DU3: Normal | DV3: 45392 | DW3: 45394 | DX3: Negative | DY3: 45397 | DZ3: BOF Fleet Safety & Compliance Policy 2024 | EA3: Complete | EB3: 45413
A4: DRV-001 | B4: John Carter | C4: 220 Demo Street, Cleveland, OH 44113 | D4: 206-555-0102 | E4: ***-**-0123 | F4: Huntington | G4: 104 | H4: 999900202 | I4: MVR Background Report | J4: VALID | K4: OH0000111 | L4: 46621 | M4: 46274 | N4: 46312 | P4: Black | Q4: Green | R4: 5'-10" | S4: 180 | T4: M | U4: 25934 | V4: DRV-001.png | W4: Caucasian | X4: jcarter@example.com | Y4: 220 Demo Street | Z4: Cleveland | AA4: OH | AB4: 44113 | AC4: OH | AD4: Class A | AE4: 44799 | AF4: N,T | AH4: 45364 | AI4: MC-0010108 | AJ4: Dr. Patricia Owens | AK4: ME100001 | AM4: Qualified | AN4: 46050 | AO4: 0 | AP4: 0 | AR4: Clear | AS4: 45392 | AT4: Authorized to Work | AU4: U.S. Passport | AX4: 45392 | AY4: BOF Onboarding Team | AZ4: Complete | BB4: Individual/Sole Proprietor | BC4: SSN | BD4: ***-**-0123 | BF4: 45392 | BG4: Received | BH4: Checking | BI4: Direct Deposit | BJ4: 45392 | BK4: Verified | BL4: 45385 | BM4: A. Reynolds | BN4: Sleeper tractor | BO4: 53 ft dry van | BP4: Cleveland, OH | BQ4: 5 | BR4: 5 | BS4: 4 | BT4: 5 | BU4: 5 | BV4: 5 | BW4: 4 | BX4: 5 | BY4: 5 | BZ4: Pass | CB4: Passed | CC4: Enrolled | CD4: Query Completed | CE4: 46037 | CF4: 46218 | CH4: Compliant | CJ4: John | CK4: Carter | CL4: OH0000077 | CM4: OH | CN4: CDL Holder | CO4: John Carter | CP4: 45364 | CQ4: 46094 | CR4: (614) 555-0107 | CS4: Dr. Patricia Owens | CT4: 45364 | CU4: OH-ME-970443 | CV4: ME100001 | CW4: Chiropractor | CX4: OH | CY4: Federal Motor Carrier Safety Regulations | DA4: No | DB4: No | DC4: No | DD4: No | DE4: No | DF4: No | DG4: Sarah Carter | DH4: Spouse | DI4: 206-555-0199 | DJ4: No | DK4: No | DL4: No | DM4: No | DN4: Yes - Appendectomy (2005) | DO4: 20/20 | DP4: 20/20 | DQ4: Pass | DR4: 118 | DS4: 78 | DT4: 72 | DU4: Normal | DV4: 45392 | DW4: 45394 | DX4: Negative | DY4: 45397 | DZ4: BOF Fleet Safety & Compliance Policy 2024 | EA4: Complete | EB4: 45413
A5: DRV-001 | B5: John Carter | C5: 220 Demo Street, Cleveland, OH 44113 | D5: 206-555-0102 | E5: ***-**-0123 | F5: Huntington | G5: 104 | H5: 999900202 | I5: Driver Application | J5: VALID | K5: OH0000127 | L5: 46621 | M5: 46275 | N5: 46313 | P5: Black | Q5: Green | R5: 5'-10" | S5: 180 | T5: M | U5: 25934 | V5: DRV-001.png | W5: Caucasian | X5: jcarter@example.com | Y5: 220 Demo Street | Z5: Cleveland | AA5: OH | AB5: 44113 | AC5: OH | AD5: Class A | AE5: 44799 | AF5: N,T | AH5: 45364 | AI5: MC-0010108 | AJ5: Dr. Patricia Owens | AK5: ME100001 | AM5: Qualified | AN5: 46050 | AO5: 0 | AP5: 0 | AR5: Clear | AS5: 45392 | AT5: Authorized to Work | AU5: U.S. Passport | AX5: 45392 | AY5: BOF Onboarding Team | AZ5: Complete | BB5: Individual/Sole Proprietor | BC5: SSN | BD5: ***-**-0123 | BF5: 45392 | BG5: Received | BH5: Checking | BI5: Direct Deposit | BJ5: 45392 | BK5: Verified | BL5: 45385 | BM5: A. Reynolds | BN5: Sleeper tractor | BO5: 53 ft dry van | BP5: Cleveland, OH | BQ5: 5 | BR5: 5 | BS5: 4 | BT5: 5 | BU5: 5 | BV5: 5 | BW5: 4 | BX5: 5 | BY5: 5 | BZ5: Pass | CB5: Passed | CC5: Enrolled | CD5: Query Completed | CE5: 46037 | CF5: 46218 | CH5: Compliant | CJ5: John | CK5: Carter | CL5: OH0000078 | CM5: OH | CN5: CDL Holder | CO5: John Carter | CP5: 45364 | CQ5: 46094 | CR5: (614) 555-0107 | CS5: Dr. Patricia Owens | CT5: 45364 | CU5: OH-ME-970443 | CV5: ME100001 | CW5: Chiropractor | CX5: OH | CY5: Federal Motor Carrier Safety Regulations | DA5: No | DB5: No | DC5: No | DD5: No | DE5: No | DF5: No | DG5: Sarah Carter | DH5: Spouse | DI5: 206-555-0199 | DJ5: No | DK5: No | DL5: No | DM5: No | DN5: Yes - Appendectomy (2005) | DO5: 20/20 | DP5: 20/20 | DQ5: Pass | DR5: 118 | DS5: 78 | DT5: 72 | DU5: Normal | DV5: 45392 | DW5: 45394 | DX5: Negative | DY5: 45397 | DZ5: BOF Fleet Safety & Compliance Policy 2024 | EA5: Complete | EB5: 45413
A6: DRV-001 | B6: John Carter | C6: 220 Demo Street, Cleveland, OH 44113 | D6: 206-555-0102 | E6: ***-**-0123 | F6: Huntington | G6: 104 | H6: 999900202 | I6: Road Test Certificate | J6: VALID | K6: OH0000137 | L6: 46621 | M6: 46276 | N6: 46314 | P6: Black | Q6: Green | R6: 5'-10" | S6: 180 | T6: M | U6: 25934 | V6: DRV-001.png | W6: Caucasian | X6: jcarter@example.com | Y6: 220 Demo Street | Z6: Cleveland | AA6: OH | AB6: 44113 | AC6: OH | AD6: Class A | AE6: 44799 | AF6: N,T | AH6: 45364 | AI6: MC-0010108 | AJ6: Dr. Patricia Owens | AK6: ME100001 | AM6: Qualified | AN6: 46050 | AO6: 0 | AP6: 0 | AR6: Clear | AS6: 45392 | AT6: Authorized to Work | AU6: U.S. Passport | AX6: 45392 | AY6: BOF Onboarding Team | AZ6: Complete | BB6: Individual/Sole Proprietor | BC6: SSN | BD6: ***-**-0123 | BF6: 45392 | BG6: Received | BH6: Checking | BI6: Direct Deposit | BJ6: 45392 | BK6: Verified | BL6: 45385 | BM6: A. Reynolds | BN6: Sleeper tractor | BO6: 53 ft dry van | BP6: Cleveland, OH | BQ6: 5 | BR6: 5 | BS6: 4 | BT6: 5 | BU6: 5 | BV6: 5 | BW6: 4 | BX6: 5 | BY6: 5 | BZ6: Pass | CB6: Passed | CC6: Enrolled | CD6: Query Completed | CE6: 46037 | CF6: 46218 | CH6: Compliant | CJ6: John | CK6: Carter | CL6: OH0000079 | CM6: OH | CN6: CDL Holder | CO6: John Carter | CP6: 45364 | CQ6: 46094 | CR6: (614) 555-0107 | CS6: Dr. Patricia Owens | CT6: 45364 | CU6: OH-ME-970443 | CV6: ME100001 | CW6: Chiropractor | CX6: OH | CY6: Federal Motor Carrier Safety Regulations | DA6: No | DB6: No | DC6: No | DD6: No | DE6: No | DF6: No | DG6: Sarah Carter | DH6: Spouse | DI6: 206-555-0199 | DJ6: No | DK6: No | DL6: No | DM6: No | DN6: Yes - Appendectomy (2005) | DO6: 20/20 | DP6: 20/20 | DQ6: Pass | DR6: 118 | DS6: 78 | DT6: 72 | DU6: Normal | DV6: 45392 | DW6: 45394 | DX6: Negative | DY6: 45397 | DZ6: BOF Fleet Safety & Compliance Policy 2024 | EA6: Complete | EB6: 45413
A7: DRV-001 | B7: John Carter | C7: 220 Demo Street, Cleveland, OH 44113 | D7: 206-555-0102 | E7: ***-**-0123 | F7: Huntington | G7: 104 | H7: 999900202 | I7: Incident/Accident Report | J7: VALID | K7: OH0000138 | L7: 46621 | M7: 46277 | N7: 46315 | O7: Load L-501: Seal mismatch detected. Pickup: SEAL-83921 Delivery: SEAL-83920. | P7: Black | Q7: Green | R7: 5'-10" | S7: 180 | T7: M | U7: 25934 | V7: DRV-001.png | W7: Caucasian | X7: jcarter@example.com | Y7: 220 Demo Street | Z7: Cleveland | AA7: OH | AB7: 44113 | AC7: OH | AD7: Class A | AE7: 44799 | AF7: N,T | AH7: 45364 | AI7: MC-0010108 | AJ7: Dr. Patricia Owens | AK7: ME100001 | AM7: Qualified | AN7: 46050 | AO7: 0 | AP7: 0 | AR7: Clear | AS7: 45392 | AT7: Authorized to Work | AU7: U.S. Passport | AX7: 45392 | AY7: BOF Onboarding Team | AZ7: Complete | BB7: Individual/Sole Proprietor | BC7: SSN | BD7: ***-**-0123 | BF7: 45392 | BG7: Received | BH7: Checking | BI7: Direct Deposit | BJ7: 45392 | BK7: Verified | BL7: 45385 | BM7: A. Reynolds | BN7: Sleeper tractor | BO7: 53 ft dry van | BP7: Cleveland, OH | BQ7: 5 | BR7: 5 | BS7: 4 | BT7: 5 | BU7: 5 | BV7: 5 | BW7: 4 | BX7: 5 | BY7: 5 | BZ7: Pass | CB7: Passed | CC7: Enrolled | CD7: Query Completed | CE7: 46037 | CF7: 46218 | CH7: Compliant | CJ7: John | CK7: Carter | CL7: OH0000080 | CM7: OH | CN7: CDL Holder | CO7: John Carter | CP7: 45364 | CQ7: 46094 | CR7: (614) 555-0107 | CS7: Dr. Patricia Owens | CT7: 45364 | CU7: OH-ME-970443 | CV7: ME100001 | CW7: Chiropractor | CX7: OH | CY7: Federal Motor Carrier Safety Regulations | DA7: No | DB7: No | DC7: No | DD7: No | DE7: No | DF7: No | DG7: Sarah Carter | DH7: Spouse | DI7: 206-555-0199 | DJ7: No | DK7: No | DL7: No | DM7: No | DN7: Yes - Appendectomy (2005) | DO7: 20/20 | DP7: 20/20 | DQ7: Pass | DR7: 118 | DS7: 78 | DT7: 72 | DU7: Normal | DV7: 45392 | DW7: 45394 | DX7: Negative | DY7: 45397 | DZ7: BOF Fleet Safety & Compliance Policy 2024 | EA7: Complete | EB7: 45413
A8: DRV-001 | B8: John Carter | C8: 220 Demo Street, Cleveland, OH 44113 | D8: 206-555-0102 | E8: ***-**-0123 | F8: Huntington | G8: 104 | H8: 999900202 | I8: Direct Deposit Form | J8: VALID | K8: OH0000124 | L8: 46621 | M8: 46278 | N8: 46316 | P8: Black | Q8: Green | R8: 5'-10" | S8: 180 | T8: M | U8: 25934 | V8: DRV-001.png | W8: Caucasian | X8: jcarter@example.com | Y8: 220 Demo Street | Z8: Cleveland | AA8: OH | AB8: 44113 | AC8: OH | AD8: Class A | AE8: 44799 | AF8: N,T | AH8: 45364 | AI8: MC-0010108 | AJ8: Dr. Patricia Owens | AK8: ME100001 | AM8: Qualified | AN8: 46050 | AO8: 0 | AP8: 0 | AR8: Clear | AS8: 45392 | AT8: Authorized to Work | AU8: U.S. Passport | AX8: 45392 | AY8: BOF Onboarding Team | AZ8: Complete | BB8: Individual/Sole Proprietor | BC8: SSN | BD8: ***-**-0123 | BF8: 45392 | BG8: Received | BH8: Checking | BI8: Direct Deposit | BJ8: 45392 | BK8: Verified | BL8: 45385 | BM8: A. Reynolds | BN8: Sleeper tractor | BO8: 53 ft dry van | BP8: Cleveland, OH | BQ8: 5 | BR8: 5 | BS8: 4 | BT8: 5 | BU8: 5 | BV8: 5 | BW8: 4 | BX8: 5 | BY8: 5 | BZ8: Pass | CB8: Passed | CC8: Enrolled | CD8: Query Completed | CE8: 46037 | CF8: 46218 | CH8: Compliant | CJ8: John | CK8: Carter | CL8: OH0000081 | CM8: OH | CN8: CDL Holder | CO8: John Carter | CP8: 45364 | CQ8: 46094 | CR8: (614) 555-0107 | CS8: Dr. Patricia Owens | CT8: 45364 | CU8: OH-ME-970443 | CV8: ME100001 | CW8: Chiropractor | CX8: OH | CY8: Federal Motor Carrier Safety Regulations | DA8: No | DB8: No | DC8: No | DD8: No | DE8: No | DF8: No | DG8: Sarah Carter | DH8: Spouse | DI8: 206-555-0199 | DJ8: No | DK8: No | DL8: No | DM8: No | DN8: Yes - Appendectomy (2005) | DO8: 20/20 | DP8: 20/20 | DQ8: Pass | DR8: 118 | DS8: 78 | DT8: 72 | DU8: Normal | DV8: 45392 | DW8: 45394 | DX8: Negative | DY8: 45397 | DZ8: BOF Fleet Safety & Compliance Policy 2024 | EA8: Complete | EB8: 45413
A9: DRV-002 | B9: Maria Lopez | C9: 770 Demo Street, Chicago, IL 60611 | D9: 707-555-0100 | E9: ***-**-0105 | F9: Chase | G9: 107 | H9: 999900201 | I9: CDL Summary | J9: VALID | K9: IL0000041 | L9: 46518 | M9: 46596 | N9: 46455 | P9: Brown | Q9: Hazel | R9: 5'-3" | S9: 134 | T9: F | U9: 30317 | V9: DRV-002.png | W9: Hispanic | X9: marialopez@example.com | Y9: 770 Demo Street | Z9: Chicago | AA9: IL | AB9: 60611 | AC9: IL | AD9: Class A | AE9: 44696 | AF9: N | AG9: Corrective lenses | AH9: 45866 | AI9: MC-0020104 | AJ9: Dr. Kevin Marshall | AK9: ME100002 | AL9: Corrective lenses | AM9: Qualified | AN9: 46425 | AO9: 1 | AP9: 0 | AQ9: Corrective lenses | AR9: Clear | AS9: 45446 | AT9: Authorized to Work | AU9: U.S. Passport | AX9: 45446 | AY9: BOF Onboarding Team | AZ9: Complete | BB9: Individual/Sole Proprietor | BC9: SSN | BD9: ***-**-0105 | BF9: 45446 | BG9: Received | BH9: Checking | BI9: Direct Deposit | BJ9: 45446 | BK9: Verified | BL9: 45439 | BM9: D. Foster | BN9: Day cab tractor | BO9: 53 ft reefer | BP9: Chicago, IL | BQ9: 4 | BR9: 5 | BS9: 4 | BT9: 4 | BU9: 5 | BV9: 5 | BW9: 4 | BX9: 5 | BY9: 4 | BZ9: Pass | CA9: Corrective lenses | CB9: Passed | CC9: Enrolled | CD9: Query Completed | CE9: 46037 | CF9: 46218 | CH9: Compliant | CJ9: Maria | CK9: Lopez | CL9: IL0000041 | CM9: IL | CN9: CDL Holder | CO9: Maria Lopez | CP9: 45866 | CQ9: 46596 | CR9: (312) 555-0101 | CS9: Dr. Kevin Marshall | CT9: 45866 | CU9: IL-ME-425674 | CV9: ME100002 | CW9: MD | CX9: IL | CY9: Federal Motor Carrier Safety Regulations | DA9: Yes | DB9: No | DC9: No | DD9: No | DE9: Yes | DF9: No | DG9: Jane Doe | DH9: Sister | DI9: 555-555-5555 | DJ9: No | DK9: No | DL9: No | DM9: No | DN9: Yes - Appendectomy (2005) | DO9: 20/20 | DP9: 20/20 | DQ9: Pass | DR9: 118 | DS9: 78 | DT9: 72 | DU9: Normal | DV9: 45392 | DW9: 45394 | DX9: Negative | DY9: 45397 | DZ9: BOF Fleet Safety & Compliance Policy 2024 | EA9: Complete | EB9: 45413
A10: DRV-002 | B10: Maria Lopez | C10: 770 Demo Street, Chicago, IL 60611 | D10: 707-555-0100 | E10: ***-**-0105 | F10: Chase | G10: 107 | H10: 999900201 | I10: Medical Certification | J10: VALID | K10: IL0000068 | L10: 46518 | M10: 46596 | N10: 46455 | P10: Brown | Q10: Hazel | R10: 5'-3" | S10: 134 | T10: F | U10: 30317 | V10: DRV-002.png | W10: Hispanic | X10: marialopez@example.com | Y10: 770 Demo Street | Z10: Chicago | AA10: IL | AB10: 60611 | AC10: IL | AD10: Class A | AE10: 44696 | AF10: N | AG10: Corrective lenses | AH10: 45866 | AI10: MC-0020104 | AJ10: Dr. Kevin Marshall | AK10: ME100002 | AL10: Corrective lenses | AM10: Qualified | AN10: 46425 | AO10: 1 | AP10: 0 | AQ10: Corrective lenses | AR10: Clear | AS10: 45446 | AT10: Authorized to Work | AU10: U.S. Passport | AX10: 45446 | AY10: BOF Onboarding Team | AZ10: Complete | BB10: Individual/Sole Proprietor | BC10: SSN | BD10: ***-**-0105 | BF10: 45446 | BG10: Received | BH10: Checking | BI10: Direct Deposit | BJ10: 45446 | BK10: Verified | BL10: 45439 | BM10: D. Foster | BN10: Day cab tractor | BO10: 53 ft reefer | BP10: Chicago, IL | BQ10: 4 | BR10: 5 | BS10: 4 | BT10: 4 | BU10: 5 | BV10: 5 | BW10: 4 | BX10: 5 | BY10: 4 | BZ10: Pass | CA10: Corrective lenses | CB10: Passed | CC10: Enrolled | CD10: Query Completed | CE10: 46037 | CF10: 46218 | CH10: Compliant | CJ10: Maria | CK10: Lopez | CL10: IL0000042 | CM10: IL | CN10: CDL Holder | CO10: Maria Lopez | CP10: 45866 | CQ10: 46596 | CR10: (312) 555-0101 | CS10: Dr. Kevin Marshall | CT10: 45866 | CU10: IL-ME-425674 | CV10: ME100002 | CW10: MD | CX10: IL | CY10: Federal Motor Carrier Safety Regulations | DA10: Yes | DB10: No | DC10: No | DD10: No | DE10: Yes | DF10: No | DG10: Jane Doe | DH10: Sister | DI10: 555-555-5555 | DJ10: No | DK10: No | DL10: No | DM10: No | DN10: Yes - Appendectomy (2005) | DO10: 20/20 | DP10: 20/20 | DQ10: Pass | DR10: 118 | DS10: 78 | DT10: 72 | DU10: Normal | DV10: 45392 | DW10: 45394 | DX10: Negative | DY10: 45397 | DZ10: BOF Fleet Safety & Compliance Policy 2024 | EA10: Complete | EB10: 45413
A11: DRV-002 | B11: Maria Lopez | C11: 770 Demo Street, Chicago, IL 60611 | D11: 707-555-0100 | E11: ***-**-0105 | F11: Chase | G11: 107 | H11: 999900201 | I11: MVR Background Report | J11: VALID | K11: IL0000056 | L11: 46518 | M11: 46596 | N11: 46455 | P11: Brown | Q11: Hazel | R11: 5'-3" | S11: 134 | T11: F | U11: 30317 | V11: DRV-002.png | W11: Hispanic | X11: marialopez@example.com | Y11: 770 Demo Street | Z11: Chicago | AA11: IL | AB11: 60611 | AC11: IL | AD11: Class A | AE11: 44696 | AF11: N | AG11: Corrective lenses | AH11: 45866 | AI11: MC-0020104 | AJ11: Dr. Kevin Marshall | AK11: ME100002 | AL11: Corrective lenses | AM11: Qualified | AN11: 46425 | AO11: 1 | AP11: 0 | AQ11: Corrective lenses | AR11: Clear | AS11: 45446 | AT11: Authorized to Work | AU11: U.S. Passport | AX11: 45446 | AY11: BOF Onboarding Team | AZ11: Complete | BB11: Individual/Sole Proprietor | BC11: SSN | BD11: ***-**-0105 | BF11: 45446 | BG11: Received | BH11: Checking | BI11: Direct Deposit | BJ11: 45446 | BK11: Verified | BL11: 45439 | BM11: D. Foster | BN11: Day cab tractor | BO11: 53 ft reefer | BP11: Chicago, IL | BQ11: 4 | BR11: 5 | BS11: 4 | BT11: 4 | BU11: 5 | BV11: 5 | BW11: 4 | BX11: 5 | BY11: 4 | BZ11: Pass | CA11: Corrective lenses | CB11: Passed | CC11: Enrolled | CD11: Query Completed | CE11: 46037 | CF11: 46218 | CH11: Compliant | CJ11: Maria | CK11: Lopez | CL11: IL0000043 | CM11: IL | CN11: CDL Holder | CO11: Maria Lopez | CP11: 45866 | CQ11: 46596 | CR11: (312) 555-0101 | CS11: Dr. Kevin Marshall | CT11: 45866 | CU11: IL-ME-425674 | CV11: ME100002 | CW11: MD | CX11: IL | CY11: Federal Motor Carrier Safety Regulations | DA11: Yes | DB11: No | DC11: No | DD11: No | DE11: Yes | DF11: No | DG11: Jane Doe | DH11: Sister | DI11: 555-555-5555 | DJ11: No | DK11: No | DL11: No | DM11: No | DN11: Yes - Appendectomy (2005) | DO11: 20/20 | DP11: 20/20 | DQ11: Pass | DR11: 118 | DS11: 78 | DT11: 72 | DU11: Normal | DV11: 45392 | DW11: 45394 | DX11: Negative | DY11: 45397 | DZ11: BOF Fleet Safety & Compliance Policy 2024 | EA11: Complete | EB11: 45413
A12: DRV-002 | B12: Maria Lopez | C12: 770 Demo Street, Chicago, IL 60611 | D12: 707-555-0100 | E12: ***-**-0105 | F12: Chase | G12: 107 | H12: 999900201 | I12: Driver Application | J12: VALID | K12: IL0000065 | L12: 46518 | M12: 46596 | N12: 46455 | P12: Brown | Q12: Hazel | R12: 5'-3" | S12: 134 | T12: F | U12: 30317 | V12: DRV-002.png | W12: Hispanic | X12: marialopez@example.com | Y12: 770 Demo Street | Z12: Chicago | AA12: IL | AB12: 60611 | AC12: IL | AD12: Class A | AE12: 44696 | AF12: N | AG12: Corrective lenses | AH12: 45866 | AI12: MC-0020104 | AJ12: Dr. Kevin Marshall | AK12: ME100002 | AL12: Corrective lenses | AM12: Qualified | AN12: 46425 | AO12: 1 | AP12: 0 | AQ12: Corrective lenses | AR12: Clear | AS12: 45446 | AT12: Authorized to Work | AU12: U.S. Passport | AX12: 45446 | AY12: BOF Onboarding Team | AZ12: Complete | BB12: Individual/Sole Proprietor | BC12: SSN | BD12: ***-**-0105 | BF12: 45446 | BG12: Received | BH12: Checking | BI12: Direct Deposit | BJ12: 45446 | BK12: Verified | BL12: 45439 | BM12: D. Foster | BN12: Day cab tractor | BO12: 53 ft reefer | BP12: Chicago, IL | BQ12: 4 | BR12: 5 | BS12: 4 | BT12: 4 | BU12: 5 | BV12: 5 | BW12: 4 | BX12: 5 | BY12: 4 | BZ12: Pass | CA12: Corrective lenses | CB12: Passed | CC12: Enrolled | CD12: Query Completed | CE12: 46037 | CF12: 46218 | CH12: Compliant | CJ12: Maria | CK12: Lopez | CL12: IL0000044 | CM12: IL | CN12: CDL Holder | CO12: Maria Lopez | CP12: 45866 | CQ12: 46596 | CR12: (312) 555-0101 | CS12: Dr. Kevin Marshall | CT12: 45866 | CU12: IL-ME-425674 | CV12: ME100002 | CW12: MD | CX12: IL | CY12: Federal Motor Carrier Safety Regulations | DA12: Yes | DB12: No | DC12: No | DD12: No | DE12: Yes | DF12: No | DG12: Jane Doe | DH12: Sister | DI12: 555-555-5555 | DJ12: No | DK12: No | DL12: No | DM12: No | DN12: Yes - Appendectomy (2005) | DO12: 20/20 | DP12: 20/20 | DQ12: Pass | DR12: 118 | DS12: 78 | DT12: 72 | DU12: Normal | DV12: 45392 | DW12: 45394 | DX12: Negative | DY12: 45397 | DZ12: BOF Fleet Safety & Compliance Policy 2024 | EA12: Complete | EB12: 45413
A13: DRV-002 | B13: Maria Lopez | C13: 770 Demo Street, Chicago, IL 60611 | D13: 707-555-0100 | E13: ***-**-0105 | F13: Chase | G13: 107 | H13: 999900201 | I13: Road Test Certificate | J13: VALID | K13: IL0000067 | L13: 46518 | M13: 46596 | N13: 46455 | P13: Brown | Q13: Hazel | R13: 5'-3" | S13: 134 | T13: F | U13: 30317 | V13: DRV-002.png | W13: Hispanic | X13: marialopez@example.com | Y13: 770 Demo Street | Z13: Chicago | AA13: IL | AB13: 60611 | AC13: IL | AD13: Class A | AE13: 44696 | AF13: N | AG13: Corrective lenses | AH13: 45866 | AI13: MC-0020104 | AJ13: Dr. Kevin Marshall | AK13: ME100002 | AL13: Corrective lenses | AM13: Qualified | AN13: 46425 | AO13: 1 | AP13: 0 | AQ13: Corrective lenses | AR13: Clear | AS13: 45446 | AT13: Authorized to Work | AU13: U.S. Passport | AX13: 45446 | AY13: BOF Onboarding Team | AZ13: Complete | BB13: Individual/Sole Proprietor | BC13: SSN | BD13: ***-**-0105 | BF13: 45446 | BG13: Received | BH13: Checking | BI13: Direct Deposit | BJ13: 45446 | BK13: Verified | BL13: 45439 | BM13: D. Foster | BN13: Day cab tractor | BO13: 53 ft reefer | BP13: Chicago, IL | BQ13: 4 | BR13: 5 | BS13: 4 | BT13: 4 | BU13: 5 | BV13: 5 | BW13: 4 | BX13: 5 | BY13: 4 | BZ13: Pass | CA13: Corrective lenses | CB13: Passed | CC13: Enrolled | CD13: Query Completed | CE13: 46037 | CF13: 46218 | CH13: Compliant | CJ13: Maria | CK13: Lopez | CL13: IL0000045 | CM13: IL | CN13: CDL Holder | CO13: Maria Lopez | CP13: 45866 | CQ13: 46596 | CR13: (312) 555-0101 | CS13: Dr. Kevin Marshall | CT13: 45866 | CU13: IL-ME-425674 | CV13: ME100002 | CW13: MD | CX13: IL | CY13: Federal Motor Carrier Safety Regulations | DA13: Yes | DB13: No | DC13: No | DD13: No | DE13: Yes | DF13: No | DG13: Jane Doe | DH13: Sister | DI13: 555-555-5555 | DJ13: No | DK13: No | DL13: No | DM13: No | DN13: Yes - Appendectomy (2005) | DO13: 20/20 | DP13: 20/20 | DQ13: Pass | DR13: 118 | DS13: 78 | DT13: 72 | DU13: Normal | DV13: 45392 | DW13: 45394 | DX13: Negative | DY13: 45397 | DZ13: BOF Fleet Safety & Compliance Policy 2024 | EA13: Complete | EB13: 45413
A14: DRV-002 | B14: Maria Lopez | C14: 770 Demo Street, Chicago, IL 60611 | D14: 707-555-0100 | E14: ***-**-0105 | F14: Chase | G14: 107 | H14: 999900201 | I14: Incident/Accident Report | J14: VALID | K14: IL0000058 | L14: 46518 | M14: 46596 | N14: 46455 | O14: No major incidents recorded in last 90 days. | P14: Brown | Q14: Hazel | R14: 5'-3" | S14: 134 | T14: F | U14: 30317 | V14: DRV-002.png | W14: Hispanic | X14: marialopez@example.com | Y14: 770 Demo Street | Z14: Chicago | AA14: IL | AB14: 60611 | AC14: IL | AD14: Class A | AE14: 44696 | AF14: N | AG14: Corrective lenses | AH14: 45866 | AI14: MC-0020104 | AJ14: Dr. Kevin Marshall | AK14: ME100002 | AL14: Corrective lenses | AM14: Qualified | AN14: 46425 | AO14: 1 | AP14: 0 | AQ14: Corrective lenses | AR14: Clear | AS14: 45446 | AT14: Authorized to Work | AU14: U.S. Passport | AX14: 45446 | AY14: BOF Onboarding Team | AZ14: Complete | BB14: Individual/Sole Proprietor | BC14: SSN | BD14: ***-**-0105 | BF14: 45446 | BG14: Received | BH14: Checking | BI14: Direct Deposit | BJ14: 45446 | BK14: Verified | BL14: 45439 | BM14: D. Foster | BN14: Day cab tractor | BO14: 53 ft reefer | BP14: Chicago, IL | BQ14: 4 | BR14: 5 | BS14: 4 | BT14: 4 | BU14: 5 | BV14: 5 | BW14: 4 | BX14: 5 | BY14: 4 | BZ14: Pass | CA14: Corrective lenses | CB14: Passed | CC14: Enrolled | CD14: Query Completed | CE14: 46037 | CF14: 46218 | CH14: Compliant | CJ14: Maria | CK14: Lopez | CL14: IL0000046 | CM14: IL | CN14: CDL Holder | CO14: Maria Lopez | CP14: 45866 | CQ14: 46596 | CR14: (312) 555-0101 | CS14: Dr. Kevin Marshall | CT14: 45866 | CU14: IL-ME-425674 | CV14: ME100002 | CW14: MD | CX14: IL | CY14: Federal Motor Carrier Safety Regulations | DA14: Yes | DB14: No | DC14: No | DD14: No | DE14: Yes | DF14: No | DG14: Jane Doe | DH14: Sister | DI14: 555-555-5555 | DJ14: No | DK14: No | DL14: No | DM14: No | DN14: Yes - Appendectomy (2005) | DO14: 20/20 | DP14: 20/20 | DQ14: Pass | DR14: 118 | DS14: 78 | DT14: 72 | DU14: Normal | DV14: 45392 | DW14: 45394 | DX14: Negative | DY14: 45397 | DZ14: BOF Fleet Safety & Compliance Policy 2024 | EA14: Complete | EB14: 45413
A15: DRV-002 | B15: Maria Lopez | C15: 770 Demo Street, Chicago, IL 60611 | D15: 707-555-0100 | E15: ***-**-0105 | F15: Chase | G15: 107 | H15: 999900201 | I15: Direct Deposit Form | J15: VALID | K15: IL0000061 | L15: 46518 | M15: 46596 | N15: 46455 | P15: Brown | Q15: Hazel | R15: 5'-3" | S15: 134 | T15: F | U15: 30317 | V15: DRV-002.png | W15: Hispanic | X15: marialopez@example.com | Y15: 770 Demo Street | Z15: Chicago | AA15: IL | AB15: 60611 | AC15: IL | AD15: Class A | AE15: 44696 | AF15: N | AG15: Corrective lenses | AH15: 45866 | AI15: MC-0020104 | AJ15: Dr. Kevin Marshall | AK15: ME100002 | AL15: Corrective lenses | AM15: Qualified | AN15: 46425 | AO15: 1 | AP15: 0 | AQ15: Corrective lenses | AR15: Clear | AS15: 45446 | AT15: Authorized to Work | AU15: U.S. Passport | AX15: 45446 | AY15: BOF Onboarding Team | AZ15: Complete | BB15: Individual/Sole Proprietor | BC15: SSN | BD15: ***-**-0105 | BF15: 45446 | BG15: Received | BH15: Checking | BI15: Direct Deposit | BJ15: 45446 | BK15: Verified | BL15: 45439 | BM15: D. Foster | BN15: Day cab tractor | BO15: 53 ft reefer | BP15: Chicago, IL | BQ15: 4 | BR15: 5 | BS15: 4 | BT15: 4 | BU15: 5 | BV15: 5 | BW15: 4 | BX15: 5 | BY15: 4 | BZ15: Pass | CA15: Corrective lenses | CB15: Passed | CC15: Enrolled | CD15: Query Completed | CE15: 46037 | CF15: 46218 | CH15: Compliant | CJ15: Maria | CK15: Lopez | CL15: IL0000047 | CM15: IL | CN15: CDL Holder | CO15: Maria Lopez | CP15: 45866 | CQ15: 46596 | CR15: (312) 555-0101 | CS15: Dr. Kevin Marshall | CT15: 45866 | CU15: IL-ME-425674 | CV15: ME100002 | CW15: MD | CX15: IL | CY15: Federal Motor Carrier Safety Regulations | DA15: Yes | DB15: No | DC15: No | DD15: No | DE15: Yes | DF15: No | DG15: Jane Doe | DH15: Sister | DI15: 555-555-5555 | DJ15: No | DK15: No | DL15: No | DM15: No | DN15: Yes - Appendectomy (2005) | DO15: 20/20 | DP15: 20/20 | DQ15: Pass | DR15: 118 | DS15: 78 | DT15: 72 | DU15: Normal | DV15: 45392 | DW15: 45394 | DX15: Negative | DY15: 45397 | DZ15: BOF Fleet Safety & Compliance Policy 2024 | EA15: Complete | EB15: 45413
A16: DRV-003 | B16: Alex Kim | C16: 960 Demo Street, Atlanta, GA 30308 | D16: 675-555-0100 | E16: ***-**-0116 | F16: Chase | G16: 111 | H16: 999900211 | I16: CDL Summary | J16: VALID | K16: GA0000013 | L16: 46420 | M16: 46659 | N16: 46449 | P16: Brown | Q16: Blue | R16: 6'-2" | S16: 214 | T16: M | U16: 25934 | V16: DRV-003.png | W16: Asian | X16: alexkim@example.com | Y16: 960 Demo Street | Z16: Atlanta | AA16: GA | AB16: 30308 | AC16: GA | AD16: Class A | AE16: 44598 | AF16: H,N | AH16: 45929 | AI16: MC-0030104 | AJ16: Dr. Lisa Bennett | AK16: ME100003 | AM16: Qualified | AN16: 46419 | AO16: 0 | AP16: 0 | AR16: Clear | AS16: 45488 | AT16: Authorized to Work | AU16: U.S. Passport | AX16: 45488 | AY16: BOF Onboarding Team | AZ16: Complete | BB16: Individual/Sole Proprietor | BC16: SSN | BD16: ***-**-0116 | BF16: 45488 | BG16: Received | BH16: Checking | BI16: Direct Deposit | BJ16: 45488 | BK16: Verified | BL16: 45481 | BM16: M. Chen | BN16: Sleeper tractor | BO16: Tanker | BP16: Atlanta, GA | BQ16: 5 | BR16: 5 | BS16: 5 | BT16: 5 | BU16: 4 | BV16: 5 | BW16: 5 | BX16: 5 | BY16: 5 | BZ16: Pass | CA16: HazMat loads only after refresher every 12 months | CB16: Passed | CC16: Enrolled | CD16: Query Completed | CE16: 46037 | CF16: 46218 | CH16: Compliant | CJ16: Alex | CK16: Kim | CL16: GA0000013 | CM16: GA | CN16: CDL Holder | CO16: Alex Kim | CP16: 45929 | CQ16: 46659 | CR16: (404) 555-0107 | CS16: Dr. Lisa Bennett | CT16: 45929 | CU16: GA-ME-142937 | CV16: ME100003 | CW16: Advanced Practice Nurse | CX16: GA | CY16: Federal Motor Carrier Safety Regulations | DA16: No | DB16: No | DC16: No | DD16: No | DE16: No | DF16: No | DG16: Jane Doe | DH16: Sister | DI16: 555-555-5555 | DJ16: No | DK16: No | DL16: No | DM16: No | DN16: Yes - Appendectomy (2005) | DO16: 20/20 | DP16: 20/20 | DQ16: Pass | DR16: 118 | DS16: 78 | DT16: 72 | DU16: Normal | DV16: 45392 | DW16: 45394 | DX16: Negative | DY16: 45397 | DZ16: BOF Fleet Safety & Compliance Policy 2024 | EA16: Complete | EB16: 45413
A17: DRV-003 | B17: Alex Kim | C17: 960 Demo Street, Atlanta, GA 30308 | D17: 675-555-0100 | E17: ***-**-0116 | F17: Chase | G17: 111 | H17: 999900211 | I17: Medical Certification | J17: VALID | K17: GA0000006 | L17: 46420 | M17: 46659 | N17: 46449 | P17: Brown | Q17: Blue | R17: 6'-2" | S17: 214 | T17: M | U17: 25934 | V17: DRV-003.png | W17: Asian | X17: alexkim@example.com | Y17: 960 Demo Street | Z17: Atlanta | AA17: GA | AB17: 30308 | AC17: GA | AD17: Class A | AE17: 44598 | AF17: H,N | AH17: 45929 | AI17: MC-0030104 | AJ17: Dr. Lisa Bennett | AK17: ME100003 | AM17: Qualified | AN17: 46419 | AO17: 0 | AP17: 0 | AR17: Clear | AS17: 45488 | AT17: Authorized to Work | AU17: U.S. Passport | AX17: 45488 | AY17: BOF Onboarding Team | AZ17: Complete | BB17: Individual/Sole Proprietor | BC17: SSN | BD17: ***-**-0116 | BF17: 45488 | BG17: Received | BH17: Checking | BI17: Direct Deposit | BJ17: 45488 | BK17: Verified | BL17: 45481 | BM17: M. Chen | BN17: Sleeper tractor | BO17: Tanker | BP17: Atlanta, GA | BQ17: 5 | BR17: 5 | BS17: 5 | BT17: 5 | BU17: 4 | BV17: 5 | BW17: 5 | BX17: 5 | BY17: 5 | BZ17: Pass | CA17: HazMat loads only after refresher every 12 months | CB17: Passed | CC17: Enrolled | CD17: Query Completed | CE17: 46037 | CF17: 46218 | CH17: Compliant | CJ17: Alex | CK17: Kim | CL17: GA0000014 | CM17: GA | CN17: CDL Holder | CO17: Alex Kim | CP17: 45929 | CQ17: 46659 | CR17: (404) 555-0107 | CS17: Dr. Lisa Bennett | CT17: 45929 | CU17: GA-ME-142937 | CV17: ME100003 | CW17: Advanced Practice Nurse | CX17: GA | CY17: Federal Motor Carrier Safety Regulations | DA17: No | DB17: No | DC17: No | DD17: No | DE17: No | DF17: No | DG17: Jane Doe | DH17: Sister | DI17: 555-555-5555 | DJ17: No | DK17: No | DL17: No | DM17: No | DN17: Yes - Appendectomy (2005) | DO17: 20/20 | DP17: 20/20 | DQ17: Pass | DR17: 118 | DS17: 78 | DT17: 72 | DU17: Normal | DV17: 45392 | DW17: 45394 | DX17: Negative | DY17: 45397 | DZ17: BOF Fleet Safety & Compliance Policy 2024 | EA17: Complete | EB17: 45413
A18: DRV-003 | B18: Alex Kim | C18: 960 Demo Street, Atlanta, GA 30308 | D18: 675-555-0100 | E18: ***-**-0116 | F18: Chase | G18: 111 | H18: 999900211 | I18: MVR Background Report | J18: VALID | K18: GA0000011 | L18: 46420 | M18: 46659 | N18: 46449 | P18: Brown | Q18: Blue | R18: 6'-2" | S18: 214 | T18: M | U18: 25934 | V18: DRV-003.png | W18: Asian | X18: alexkim@example.com | Y18: 960 Demo Street | Z18: Atlanta | AA18: GA | AB18: 30308 | AC18: GA | AD18: Class A | AE18: 44598 | AF18: H,N | AH18: 45929 | AI18: MC-0030104 | AJ18: Dr. Lisa Bennett | AK18: ME100003 | AM18: Qualified | AN18: 46419 | AO18: 0 | AP18: 0 | AR18: Clear | AS18: 45488 | AT18: Authorized to Work | AU18: U.S. Passport | AX18: 45488 | AY18: BOF Onboarding Team | AZ18: Complete | BB18: Individual/Sole Proprietor | BC18: SSN | BD18: ***-**-0116 | BF18: 45488 | BG18: Received | BH18: Checking | BI18: Direct Deposit | BJ18: 45488 | BK18: Verified | BL18: 45481 | BM18: M. Chen | BN18: Sleeper tractor | BO18: Tanker | BP18: Atlanta, GA | BQ18: 5 | BR18: 5 | BS18: 5 | BT18: 5 | BU18: 4 | BV18: 5 | BW18: 5 | BX18: 5 | BY18: 5 | BZ18: Pass | CA18: HazMat loads only after refresher every 12 months | CB18: Passed | CC18: Enrolled | CD18: Query Completed | CE18: 46037 | CF18: 46218 | CH18: Compliant | CJ18: Alex | CK18: Kim | CL18: GA0000015 | CM18: GA | CN18: CDL Holder | CO18: Alex Kim | CP18: 45929 | CQ18: 46659 | CR18: (404) 555-0107 | CS18: Dr. Lisa Bennett | CT18: 45929 | CU18: GA-ME-142937 | CV18: ME100003 | CW18: Advanced Practice Nurse | CX18: GA | CY18: Federal Motor Carrier Safety Regulations | DA18: No | DB18: No | DC18: No | DD18: No | DE18: No | DF18: No | DG18: Jane Doe | DH18: Sister | DI18: 555-555-5555 | DJ18: No | DK18: No | DL18: No | DM18: No | DN18: Yes - Appendectomy (2005) | DO18: 20/20 | DP18: 20/20 | DQ18: Pass | DR18: 118 | DS18: 78 | DT18: 72 | DU18: Normal | DV18: 45392 | DW18: 45394 | DX18: Negative | DY18: 45397 | DZ18: BOF Fleet Safety & Compliance Policy 2024 | EA18: Complete | EB18: 45413
A19: DRV-003 | B19: Alex Kim | C19: 960 Demo Street, Atlanta, GA 30308 | D19: 675-555-0100 | E19: ***-**-0116 | F19: Chase | G19: 111 | H19: 999900211 | I19: Driver Application | J19: VALID | K19: GA0000005 | L19: 46420 | M19: 46659 | N19: 46449 | P19: Brown | Q19: Blue | R19: 6'-2" | S19: 214 | T19: M | U19: 25934 | V19: DRV-003.png | W19: Asian | X19: alexkim@example.com | Y19: 960 Demo Street | Z19: Atlanta | AA19: GA | AB19: 30308 | AC19: GA | AD19: Class A | AE19: 44598 | AF19: H,N | AH19: 45929 | AI19: MC-0030104 | AJ19: Dr. Lisa Bennett | AK19: ME100003 | AM19: Qualified | AN19: 46419 | AO19: 0 | AP19: 0 | AR19: Clear | AS19: 45488 | AT19: Authorized to Work | AU19: U.S. Passport | AX19: 45488 | AY19: BOF Onboarding Team | AZ19: Complete | BB19: Individual/Sole Proprietor | BC19: SSN | BD19: ***-**-0116 | BF19: 45488 | BG19: Received | BH19: Checking | BI19: Direct Deposit | BJ19: 45488 | BK19: Verified | BL19: 45481 | BM19: M. Chen | BN19: Sleeper tractor | BO19: Tanker | BP19: Atlanta, GA | BQ19: 5 | BR19: 5 | BS19: 5 | BT19: 5 | BU19: 4 | BV19: 5 | BW19: 5 | BX19: 5 | BY19: 5 | BZ19: Pass | CA19: HazMat loads only after refresher every 12 months | CB19: Passed | CC19: Enrolled | CD19: Query Completed | CE19: 46037 | CF19: 46218 | CH19: Compliant | CJ19: Alex | CK19: Kim | CL19: GA0000016 | CM19: GA | CN19: CDL Holder | CO19: Alex Kim | CP19: 45929 | CQ19: 46659 | CR19: (404) 555-0107 | CS19: Dr. Lisa Bennett | CT19: 45929 | CU19: GA-ME-142937 | CV19: ME100003 | CW19: Advanced Practice Nurse | CX19: GA | CY19: Federal Motor Carrier Safety Regulations | DA19: No | DB19: No | DC19: No | DD19: No | DE19: No | DF19: No | DG19: Jane Doe | DH19: Sister | DI19: 555-555-5555 | DJ19: No | DK19: No | DL19: No | DM19: No | DN19: Yes - Appendectomy (2005) | DO19: 20/20 | DP19: 20/20 | DQ19: Pass | DR19: 118 | DS19: 78 | DT19: 72 | DU19: Normal | DV19: 45392 | DW19: 45394 | DX19: Negative | DY19: 45397 | DZ19: BOF Fleet Safety & Compliance Policy 2024 | EA19: Complete | EB19: 45413
A20: DRV-003 | B20: Alex Kim | C20: 960 Demo Street, Atlanta, GA 30308 | D20: 675-555-0100 | E20: ***-**-0116 | F20: Chase | G20: 111 | H20: 999900211 | I20: Road Test Certificate | J20: VALID | K20: GA0000004 | L20: 46420 | M20: 46659 | N20: 46449 | P20: Brown | Q20: Blue | R20: 6'-2" | S20: 214 | T20: M | U20: 25934 | V20: DRV-003.png | W20: Asian | X20: alexkim@example.com | Y20: 960 Demo Street | Z20: Atlanta | AA20: GA | AB20: 30308 | AC20: GA | AD20: Class A | AE20: 44598 | AF20: H,N | AH20: 45929 | AI20: MC-0030104 | AJ20: Dr. Lisa Bennett | AK20: ME100003 | AM20: Qualified | AN20: 46419 | AO20: 0 | AP20: 0 | AR20: Clear | AS20: 45488 | AT20: Authorized to Work | AU20: U.S. Passport | AX20: 45488 | AY20: BOF Onboarding Team | AZ20: Complete | BB20: Individual/Sole Proprietor | BC20: SSN | BD20: ***-**-0116 | BF20: 45488 | BG20: Received | BH20: Checking | BI20: Direct Deposit | BJ20: 45488 | BK20: Verified | BL20: 45481 | BM20: M. Chen | BN20: Sleeper tractor | BO20: Tanker | BP20: Atlanta, GA | BQ20: 5 | BR20: 5 | BS20: 5 | BT20: 5 | BU20: 4 | BV20: 5 | BW20: 5 | BX20: 5 | BY20: 5 | BZ20: Pass | CA20: HazMat loads only after refresher every 12 months | CB20: Passed | CC20: Enrolled | CD20: Query Completed | CE20: 46037 | CF20: 46218 | CH20: Compliant | CJ20: Alex | CK20: Kim | CL20: GA0000017 | CM20: GA | CN20: CDL Holder | CO20: Alex Kim | CP20: 45929 | CQ20: 46659 | CR20: (404) 555-0107 | CS20: Dr. Lisa Bennett | CT20: 45929 | CU20: GA-ME-142937 | CV20: ME100003 | CW20: Advanced Practice Nurse | CX20: GA | CY20: Federal Motor Carrier Safety Regulations | DA20: No | DB20: No | DC20: No | DD20: No | DE20: No | DF20: No | DG20: Jane Doe | DH20: Sister | DI20: 555-555-5555 | DJ20: No | DK20: No | DL20: No | DM20: No | DN20: Yes - Appendectomy (2005) | DO20: 20/20 | DP20: 20/20 | DQ20: Pass | DR20: 118 | DS20: 78 | DT20: 72 | DU20: Normal | DV20: 45392 | DW20: 45394 | DX20: Negative | DY20: 45397 | DZ20: BOF Fleet Safety & Compliance Policy 2024 | EA20: Complete | EB20: 45413
A21: DRV-003 | B21: Alex Kim | C21: 960 Demo Street, Atlanta, GA 30308 | D21: 675-555-0100 | E21: ***-**-0116 | F21: Chase | G21: 111 | H21: 999900211 | I21: Incident/Accident Report | J21: VALID | K21: GA0000027 | L21: 46420 | M21: 46659 | N21: 46449 | O21: No major incidents recorded in last 90 days. | P21: Brown | Q21: Blue | R21: 6'-2" | S21: 214 | T21: M | U21: 25934 | V21: DRV-003.png | W21: Asian | X21: alexkim@example.com | Y21: 960 Demo Street | Z21: Atlanta | AA21: GA | AB21: 30308 | AC21: GA | AD21: Class A | AE21: 44598 | AF21: H,N | AH21: 45929 | AI21: MC-0030104 | AJ21: Dr. Lisa Bennett | AK21: ME100003 | AM21: Qualified | AN21: 46419 | AO21: 0 | AP21: 0 | AR21: Clear | AS21: 45488 | AT21: Authorized to Work | AU21: U.S. Passport | AX21: 45488 | AY21: BOF Onboarding Team | AZ21: Complete | BB21: Individual/Sole Proprietor | BC21: SSN | BD21: ***-**-0116 | BF21: 45488 | BG21: Received | BH21: Checking | BI21: Direct Deposit | BJ21: 45488 | BK21: Verified | BL21: 45481 | BM21: M. Chen | BN21: Sleeper tractor | BO21: Tanker | BP21: Atlanta, GA | BQ21: 5 | BR21: 5 | BS21: 5 | BT21: 5 | BU21: 4 | BV21: 5 | BW21: 5 | BX21: 5 | BY21: 5 | BZ21: Pass | CA21: HazMat loads only after refresher every 12 months | CB21: Passed | CC21: Enrolled | CD21: Query Completed | CE21: 46037 | CF21: 46218 | CH21: Compliant | CJ21: Alex | CK21: Kim | CL21: GA0000018 | CM21: GA | CN21: CDL Holder | CO21: Alex Kim | CP21: 45929 | CQ21: 46659 | CR21: (404) 555-0107 | CS21: Dr. Lisa Bennett | CT21: 45929 | CU21: GA-ME-142937 | CV21: ME100003 | CW21: Advanced Practice Nurse | CX21: GA | CY21: Federal Motor Carrier Safety Regulations | DA21: No | DB21: No | DC21: No | DD21: No | DE21: No | DF21: No | DG21: Jane Doe | DH21: Sister | DI21: 555-555-5555 | DJ21: No | DK21: No | DL21: No | DM21: No | DN21: Yes - Appendectomy (2005) | DO21: 20/20 | DP21: 20/20 | DQ21: Pass | DR21: 118 | DS21: 78 | DT21: 72 | DU21: Normal | DV21: 45392 | DW21: 45394 | DX21: Negative | DY21: 45397 | DZ21: BOF Fleet Safety & Compliance Policy 2024 | EA21: Complete | EB21: 45413
A22: DRV-003 | B22: Alex Kim | C22: 960 Demo Street, Atlanta, GA 30308 | D22: 675-555-0100 | E22: ***-**-0116 | F22: Chase | G22: 111 | H22: 999900211 | I22: Direct Deposit Form | J22: VALID | K22: GA0000002 | L22: 46420 | M22: 46659 | N22: 46449 | P22: Brown | Q22: Blue | R22: 6'-2" | S22: 214 | T22: M | U22: 25934 | V22: DRV-003.png | W22: Asian | X22: alexkim@example.com | Y22: 960 Demo Street | Z22: Atlanta | AA22: GA | AB22: 30308 | AC22: GA | AD22: Class A | AE22: 44598 | AF22: H,N | AH22: 45929 | AI22: MC-0030104 | AJ22: Dr. Lisa Bennett | AK22: ME100003 | AM22: Qualified | AN22: 46419 | AO22: 0 | AP22: 0 | AR22: Clear | AS22: 45488 | AT22: Authorized to Work | AU22: U.S. Passport | AX22: 45488 | AY22: BOF Onboarding Team | AZ22: Complete | BB22: Individual/Sole Proprietor | BC22: SSN | BD22: ***-**-0116 | BF22: 45488 | BG22: Received | BH22: Checking | BI22: Direct Deposit | BJ22: 45488 | BK22: Verified | BL22: 45481 | BM22: M. Chen | BN22: Sleeper tractor | BO22: Tanker | BP22: Atlanta, GA | BQ22: 5 | BR22: 5 | BS22: 5 | BT22: 5 | BU22: 4 | BV22: 5 | BW22: 5 | BX22: 5 | BY22: 5 | BZ22: Pass | CA22: HazMat loads only after refresher every 12 months | CB22: Passed | CC22: Enrolled | CD22: Query Completed | CE22: 46037 | CF22: 46218 | CH22: Compliant | CJ22: Alex | CK22: Kim | CL22: GA0000019 | CM22: GA | CN22: CDL Holder | CO22: Alex Kim | CP22: 45929 | CQ22: 46659 | CR22: (404) 555-0107 | CS22: Dr. Lisa Bennett | CT22: 45929 | CU22: GA-ME-142937 | CV22: ME100003 | CW22: Advanced Practice Nurse | CX22: GA | CY22: Federal Motor Carrier Safety Regulations | DA22: No | DB22: No | DC22: No | DD22: No | DE22: No | DF22: No | DG22: Jane Doe | DH22: Sister | DI22: 555-555-5555 | DJ22: No | DK22: No | DL22: No | DM22: No | DN22: Yes - Appendectomy (2005) | DO22: 20/20 | DP22: 20/20 | DQ22: Pass | DR22: 118 | DS22: 78 | DT22: 72 | DU22: Normal | DV22: 45392 | DW22: 45394 | DX22: Negative | DY22: 45397 | DZ22: BOF Fleet Safety & Compliance Policy 2024 | EA22: Complete | EB22: 45413
A23: DRV-004 | B23: Priya Patel | C23: 520 Demo Street, Cleveland, OH 44114 | D23: 359-555-0100 | E23: ***-**-0119 | F23: Chase | G23: 101 | H23: 999900203 | I23: CDL Summary | J23: VALID | K23: OH0000130 | L23: 46739 | M23: 46486 | N23: 46452 | P23: Brown | Q23: Blue | R23: 5'-7" | S23: 148 | T23: F | U23: 33970 | V23: DRV-004.png | W23: South Asian | X23: priyapatel@example.com | Y23: 520 Demo Street | Z23: Cleveland | AA23: OH | AB23: 44114 | AC23: OH | AD23: Class A | AE23: 44917 | AF23: N,T | AG23: Automatic transmission only | AH23: 45756 | AI23: MC-0040812 | AJ23: Dr. Ramon Ortiz | AK23: ME100004 | AM23: Qualified | AN23: 46422 | AO23: 0 | AP23: 0 | AQ23: Automatic transmission only | AR23: Clear | AS23: 45432 | AT23: Authorized to Work | AU23: U.S. Passport | AX23: 45432 | AY23: BOF Onboarding Team | AZ23: Complete | BB23: Individual/Sole Proprietor | BC23: SSN | BD23: ***-**-0119 | BF23: 45432 | BG23: Received | BH23: Savings | BI23: Direct Deposit | BJ23: 45432 | BK23: Verified | BL23: 45425 | BM23: S. Howard | BN23: Day cab tractor | BO23: 53 ft dry van | BP23: Cleveland, OH | BQ23: 4 | BR23: 4 | BS23: 4 | BT23: 5 | BU23: 4 | BV23: 4 | BW23: 4 | BX23: 5 | BY23: 4 | BZ23: Pass | CA23: Automatic transmission assigned | CB23: Passed | CC23: Enrolled | CD23: Query Completed | CE23: 46037 | CF23: 46218 | CH23: Compliant | CJ23: Priya | CK23: Patel | CL23: OH0000130 | CM23: OH | CN23: CDL Holder | CO23: Priya Patel | CP23: 45756 | CQ23: 46486 | CR23: (614) 555-0111 | CS23: Dr. Ramon Ortiz | CT23: 45756 | CU23: OH-ME-293591 | CV23: ME100004 | CW23: MD | CX23: OH | CY23: Federal Motor Carrier Safety Regulations | DA23: No | DB23: No | DC23: No | DD23: No | DE23: No | DF23: No | DG23: Jane Doe | DH23: Sister | DI23: 555-555-5555 | DJ23: No | DK23: No | DL23: No | DM23: No | DN23: Yes - Appendectomy (2005) | DO23: 20/20 | DP23: 20/20 | DQ23: Pass | DR23: 118 | DS23: 78 | DT23: 72 | DU23: Normal | DV23: 45392 | DW23: 45394 | DX23: Negative | DY23: 45397 | DZ23: BOF Fleet Safety & Compliance Policy 2024 | EA23: Complete | EB23: 45413
A24: DRV-004 | B24: Priya Patel | C24: 520 Demo Street, Cleveland, OH 44114 | D24: 359-555-0100 | E24: ***-**-0119 | F24: Chase | G24: 101 | H24: 999900203 | I24: Medical Certification | J24: VALID | K24: OH0000099 | L24: 46739 | M24: 46486 | N24: 46452 | P24: Brown | Q24: Blue | R24: 5'-7" | S24: 148 | T24: F | U24: 33970 | V24: DRV-004.png | W24: South Asian | X24: priyapatel@example.com | Y24: 520 Demo Street | Z24: Cleveland | AA24: OH | AB24: 44114 | AC24: OH | AD24: Class A | AE24: 44917 | AF24: N,T | AG24: Automatic transmission only | AH24: 45756 | AI24: MC-0040812 | AJ24: Dr. Ramon Ortiz | AK24: ME100004 | AM24: Qualified | AN24: 46422 | AO24: 0 | AP24: 0 | AQ24: Automatic transmission only | AR24: Clear | AS24: 45432 | AT24: Authorized to Work | AU24: U.S. Passport | AX24: 45432 | AY24: BOF Onboarding Team | AZ24: Complete | BB24: Individual/Sole Proprietor | BC24: SSN | BD24: ***-**-0119 | BF24: 45432 | BG24: Received | BH24: Savings | BI24: Direct Deposit | BJ24: 45432 | BK24: Verified | BL24: 45425 | BM24: S. Howard | BN24: Day cab tractor | BO24: 53 ft dry van | BP24: Cleveland, OH | BQ24: 4 | BR24: 4 | BS24: 4 | BT24: 5 | BU24: 4 | BV24: 4 | BW24: 4 | BX24: 5 | BY24: 4 | BZ24: Pass | CA24: Automatic transmission assigned | CB24: Passed | CC24: Enrolled | CD24: Query Completed | CE24: 46037 | CF24: 46218 | CH24: Compliant | CJ24: Priya | CK24: Patel | CL24: OH0000131 | CM24: OH | CN24: CDL Holder | CO24: Priya Patel | CP24: 45756 | CQ24: 46486 | CR24: (614) 555-0111 | CS24: Dr. Ramon Ortiz | CT24: 45756 | CU24: OH-ME-293591 | CV24: ME100004 | CW24: MD | CX24: OH | CY24: Federal Motor Carrier Safety Regulations | DA24: No | DB24: No | DC24: No | DD24: No | DE24: No | DF24: No | DG24: Jane Doe | DH24: Sister | DI24: 555-555-5555 | DJ24: No | DK24: No | DL24: No | DM24: No | DN24: Yes - Appendectomy (2005) | DO24: 20/20 | DP24: 20/20 | DQ24: Pass | DR24: 118 | DS24: 78 | DT24: 72 | DU24: Normal | DV24: 45392 | DW24: 45394 | DX24: Negative | DY24: 45397 | DZ24: BOF Fleet Safety & Compliance Policy 2024 | EA24: Complete | EB24: 45413
A25: DRV-004 | B25: Priya Patel | C25: 520 Demo Street, Cleveland, OH 44114 | D25: 359-555-0100 | E25: ***-**-0119 | F25: Chase | G25: 101 | H25: 999900203 | I25: MVR Background Report | J25: VALID | K25: OH0000123 | L25: 46739 | M25: 46486 | N25: 46452 | P25: Brown | Q25: Blue | R25: 5'-7" | S25: 148 | T25: F | U25: 33970 | V25: DRV-004.png | W25: South Asian | X25: priyapatel@example.com | Y25: 520 Demo Street | Z25: Cleveland | AA25: OH | AB25: 44114 | AC25: OH | AD25: Class A | AE25: 44917 | AF25: N,T | AG25: Automatic transmission only | AH25: 45756 | AI25: MC-0040812 | AJ25: Dr. Ramon Ortiz | AK25: ME100004 | AM25: Qualified | AN25: 46422 | AO25: 0 | AP25: 0 | AQ25: Automatic transmission only | AR25: Clear | AS25: 45432 | AT25: Authorized to Work | AU25: U.S. Passport | AX25: 45432 | AY25: BOF Onboarding Team | AZ25: Complete | BB25: Individual/Sole Proprietor | BC25: SSN | BD25: ***-**-0119 | BF25: 45432 | BG25: Received | BH25: Savings | BI25: Direct Deposit | BJ25: 45432 | BK25: Verified | BL25: 45425 | BM25: S. Howard | BN25: Day cab tractor | BO25: 53 ft dry van | BP25: Cleveland, OH | BQ25: 4 | BR25: 4 | BS25: 4 | BT25: 5 | BU25: 4 | BV25: 4 | BW25: 4 | BX25: 5 | BY25: 4 | BZ25: Pass | CA25: Automatic transmission assigned | CB25: Passed | CC25: Enrolled | CD25: Query Completed | CE25: 46037 | CF25: 46218 | CH25: Compliant | CJ25: Priya | CK25: Patel | CL25: OH0000132 | CM25: OH | CN25: CDL Holder | CO25: Priya Patel | CP25: 45756 | CQ25: 46486 | CR25: (614) 555-0111 | CS25: Dr. Ramon Ortiz | CT25: 45756 | CU25: OH-ME-293591 | CV25: ME100004 | CW25: MD | CX25: OH | CY25: Federal Motor Carrier Safety Regulations | DA25: No | DB25: No | DC25: No | DD25: No | DE25: No | DF25: No | DG25: Jane Doe | DH25: Sister | DI25: 555-555-5555 | DJ25: No | DK25: No | DL25: No | DM25: No | DN25: Yes - Appendectomy (2005) | DO25: 20/20 | DP25: 20/20 | DQ25: Pass | DR25: 118 | DS25: 78 | DT25: 72 | DU25: Normal | DV25: 45392 | DW25: 45394 | DX25: Negative | DY25: 45397 | DZ25: BOF Fleet Safety & Compliance Policy 2024 | EA25: Complete | EB25: 45413
A26: DRV-004 | B26: Priya Patel | C26: 520 Demo Street, Cleveland, OH 44114 | D26: 359-555-0100 | E26: ***-**-0119 | F26: Chase | G26: 101 | H26: 999900203 | I26: summary | J26: VALID | K26: OH0000149 | L26: 46739 | M26: 46486 | N26: 46452 | P26: Brown | Q26: Blue | R26: 5'-7" | S26: 148 | T26: F | U26: 33970 | V26: DRV-004.png | W26: South Asian | X26: priyapatel@example.com | Y26: 520 Demo Street | Z26: Cleveland | AA26: OH | AB26: 44114 | AC26: OH | AD26: Class A | AE26: 44917 | AF26: N,T | AG26: Automatic transmission only | AH26: 45756 | AI26: MC-0040812 | AJ26: Dr. Ramon Ortiz | AK26: ME100004 | AM26: Qualified | AN26: 46422 | AO26: 0 | AP26: 0 | AQ26: Automatic transmission only | AR26: Clear | AS26: 45432 | AT26: Authorized to Work | AU26: U.S. Passport | AX26: 45432 | AY26: BOF Onboarding Team | AZ26: Complete | BB26: Individual/Sole Proprietor | BC26: SSN | BD26: ***-**-0119 | BF26: 45432 | BG26: Received | BH26: Savings | BI26: Direct Deposit | BJ26: 45432 | BK26: Verified | BL26: 45425 | BM26: S. Howard | BN26: Day cab tractor | BO26: 53 ft dry van | BP26: Cleveland, OH | BQ26: 4 | BR26: 4 | BS26: 4 | BT26: 5 | BU26: 4 | BV26: 4 | BW26: 4 | BX26: 5 | BY26: 4 | BZ26: Pass | CA26: Automatic transmission assigned | CB26: Passed | CC26: Enrolled | CD26: Query Completed | CE26: 46037 | CF26: 46218 | CH26: Compliant | CJ26: Priya | CK26: Patel | CL26: OH0000133 | CM26: OH | CN26: CDL Holder | CO26: Priya Patel | CP26: 45756 | CQ26: 46486 | CR26: (614) 555-0111 | CS26: Dr. Ramon Ortiz | CT26: 45756 | CU26: OH-ME-293591 | CV26: ME100004 | CW26: MD | CX26: OH | CY26: Federal Motor Carrier Safety Regulations | DA26: No | DB26: No | DC26: No | DD26: No | DE26: No | DF26: No | DG26: Jane Doe | DH26: Sister | DI26: 555-555-5555 | DJ26: No | DK26: No | DL26: No | DM26: No | DN26: Yes - Appendectomy (2005) | DO26: 20/20 | DP26: 20/20 | DQ26: Pass | DR26: 118 | DS26: 78 | DT26: 72 | DU26: Normal | DV26: 45392 | DW26: 45394 | DX26: Negative | DY26: 45397 | DZ26: BOF Fleet Safety & Compliance Policy 2024 | EA26: Complete | EB26: 45413
A27: DRV-004 | B27: Priya Patel | C27: 520 Demo Street, Cleveland, OH 44114 | D27: 359-555-0100 | E27: ***-**-0119 | F27: Chase | G27: 101 | H27: 999900203 | I27: Road Test Certificate | J27: VALID | K27: OH0000072 | L27: 46739 | M27: 46486 | N27: 46452 | P27: Brown | Q27: Blue | R27: 5'-7" | S27: 148 | T27: F | U27: 33970 | V27: DRV-004.png | W27: South Asian | X27: priyapatel@example.com | Y27: 520 Demo Street | Z27: Cleveland | AA27: OH | AB27: 44114 | AC27: OH | AD27: Class A | AE27: 44917 | AF27: N,T | AG27: Automatic transmission only | AH27: 45756 | AI27: MC-0040812 | AJ27: Dr. Ramon Ortiz | AK27: ME100004 | AM27: Qualified | AN27: 46422 | AO27: 0 | AP27: 0 | AQ27: Automatic transmission only | AR27: Clear | AS27: 45432 | AT27: Authorized to Work | AU27: U.S. Passport | AX27: 45432 | AY27: BOF Onboarding Team | AZ27: Complete | BB27: Individual/Sole Proprietor | BC27: SSN | BD27: ***-**-0119 | BF27: 45432 | BG27: Received | BH27: Savings | BI27: Direct Deposit | BJ27: 45432 | BK27: Verified | BL27: 45425 | BM27: S. Howard | BN27: Day cab tractor | BO27: 53 ft dry van | BP27: Cleveland, OH | BQ27: 4 | BR27: 4 | BS27: 4 | BT27: 5 | BU27: 4 | BV27: 4 | BW27: 4 | BX27: 5 | BY27: 4 | BZ27: Pass | CA27: Automatic transmission assigned | CB27: Passed | CC27: Enrolled | CD27: Query Completed | CE27: 46037 | CF27: 46218 | CH27: Compliant | CJ27: Priya | CK27: Patel | CL27: OH0000134 | CM27: OH | CN27: CDL Holder | CO27: Priya Patel | CP27: 45756 | CQ27: 46486 | CR27: (614) 555-0111 | CS27: Dr. Ramon Ortiz | CT27: 45756 | CU27: OH-ME-293591 | CV27: ME100004 | CW27: MD | CX27: OH | CY27: Federal Motor Carrier Safety Regulations | DA27: No | DB27: No | DC27: No | DD27: No | DE27: No | DF27: No | DG27: Jane Doe | DH27: Sister | DI27: 555-555-5555 | DJ27: No | DK27: No | DL27: No | DM27: No | DN27: Yes - Appendectomy (2005) | DO27: 20/20 | DP27: 20/20 | DQ27: Pass | DR27: 118 | DS27: 78 | DT27: 72 | DU27: Normal | DV27: 45392 | DW27: 45394 | DX27: Negative | DY27: 45397 | DZ27: BOF Fleet Safety & Compliance Policy 2024 | EA27: Complete | EB27: 45413
A28: DRV-004 | B28: Priya Patel | C28: 520 Demo Street, Cleveland, OH 44114 | D28: 359-555-0100 | E28: ***-**-0119 | F28: Chase | G28: 101 | H28: 999900203 | I28: Incident/Accident Report | J28: VALID | K28: OH0000074 | L28: 46739 | M28: 46486 | N28: 46452 | O28: Load L-504: Seal mismatch detected. Pickup: SEAL-61044 Delivery: SEAL-61043. | P28: Brown | Q28: Blue | R28: 5'-7" | S28: 148 | T28: F | U28: 33970 | V28: DRV-004.png | W28: South Asian | X28: priyapatel@example.com | Y28: 520 Demo Street | Z28: Cleveland | AA28: OH | AB28: 44114 | AC28: OH | AD28: Class A | AE28: 44917 | AF28: N,T | AG28: Automatic transmission only | AH28: 45756 | AI28: MC-0040812 | AJ28: Dr. Ramon Ortiz | AK28: ME100004 | AM28: Qualified | AN28: 46422 | AO28: 0 | AP28: 0 | AQ28: Automatic transmission only | AR28: Clear | AS28: 45432 | AT28: Authorized to Work | AU28: U.S. Passport | AX28: 45432 | AY28: BOF Onboarding Team | AZ28: Complete | BB28: Individual/Sole Proprietor | BC28: SSN | BD28: ***-**-0119 | BF28: 45432 | BG28: Received | BH28: Savings | BI28: Direct Deposit | BJ28: 45432 | BK28: Verified | BL28: 45425 | BM28: S. Howard | BN28: Day cab tractor | BO28: 53 ft dry van | BP28: Cleveland, OH | BQ28: 4 | BR28: 4 | BS28: 4 | BT28: 5 | BU28: 4 | BV28: 4 | BW28: 4 | BX28: 5 | BY28: 4 | BZ28: Pass | CA28: Automatic transmission assigned | CB28: Passed | CC28: Enrolled | CD28: Query Completed | CE28: 46037 | CF28: 46218 | CH28: Compliant | CJ28: Priya | CK28: Patel | CL28: OH0000135 | CM28: OH | CN28: CDL Holder | CO28: Priya Patel | CP28: 45756 | CQ28: 46486 | CR28: (614) 555-0111 | CS28: Dr. Ramon Ortiz | CT28: 45756 | CU28: OH-ME-293591 | CV28: ME100004 | CW28: MD | CX28: OH | CY28: Federal Motor Carrier Safety Regulations | DA28: No | DB28: No | DC28: No | DD28: No | DE28: No | DF28: No | DG28: Jane Doe | DH28: Sister | DI28: 555-555-5555 | DJ28: No | DK28: No | DL28: No | DM28: No | DN28: Yes - Appendectomy (2005) | DO28: 20/20 | DP28: 20/20 | DQ28: Pass | DR28: 118 | DS28: 78 | DT28: 72 | DU28: Normal | DV28: 45392 | DW28: 45394 | DX28: Negative | DY28: 45397 | DZ28: BOF Fleet Safety & Compliance Policy 2024 | EA28: Complete | EB28: 45413
A29: DRV-004 | B29: Priya Patel | C29: 520 Demo Street, Cleveland, OH 44114 | D29: 359-555-0100 | E29: ***-**-0119 | F29: Chase | G29: 101 | H29: 999900203 | I29: Direct Deposit Form | J29: VALID | K29: OH0000095 | L29: 46739 | M29: 46486 | N29: 46452 | P29: Brown | Q29: Blue | R29: 5'-7" | S29: 148 | T29: F | U29: 33970 | V29: DRV-004.png | W29: South Asian | X29: priyapatel@example.com | Y29: 520 Demo Street | Z29: Cleveland | AA29: OH | AB29: 44114 | AC29: OH | AD29: Class A | AE29: 44917 | AF29: N,T | AG29: Automatic transmission only | AH29: 45756 | AI29: MC-0040812 | AJ29: Dr. Ramon Ortiz | AK29: ME100004 | AM29: Qualified | AN29: 46422 | AO29: 0 | AP29: 0 | AQ29: Automatic transmission only | AR29: Clear | AS29: 45432 | AT29: Authorized to Work | AU29: U.S. Passport | AX29: 45432 | AY29: BOF Onboarding Team | AZ29: Complete | BB29: Individual/Sole Proprietor | BC29: SSN | BD29: ***-**-0119 | BF29: 45432 | BG29: Received | BH29: Savings | BI29: Direct Deposit | BJ29: 45432 | BK29: Verified | BL29: 45425 | BM29: S. Howard | BN29: Day cab tractor | BO29: 53 ft dry van | BP29: Cleveland, OH | BQ29: 4 | BR29: 4 | BS29: 4 | BT29: 5 | BU29: 4 | BV29: 4 | BW29: 4 | BX29: 5 | BY29: 4 | BZ29: Pass | CA29: Automatic transmission assigned | CB29: Passed | CC29: Enrolled | CD29: Query Completed | CE29: 46037 | CF29: 46218 | CH29: Compliant | CJ29: Priya | CK29: Patel | CL29: OH0000136 | CM29: OH | CN29: CDL Holder | CO29: Priya Patel | CP29: 45756 | CQ29: 46486 | CR29: (614) 555-0111 | CS29: Dr. Ramon Ortiz | CT29: 45756 | CU29: OH-ME-293591 | CV29: ME100004 | CW29: MD | CX29: OH | CY29: Federal Motor Carrier Safety Regulations | DA29: No | DB29: No | DC29: No | DD29: No | DE29: No | DF29: No | DG29: Jane Doe | DH29: Sister | DI29: 555-555-5555 | DJ29: No | DK29: No | DL29: No | DM29: No | DN29: Yes - Appendectomy (2005) | DO29: 20/20 | DP29: 20/20 | DQ29: Pass | DR29: 118 | DS29: 78 | DT29: 72 | DU29: Normal | DV29: 45392 | DW29: 45394 | DX29: Negative | DY29: 45397 | DZ29: BOF Fleet Safety & Compliance Policy 2024 | EA29: Complete | EB29: 45413
